Workbook

Sheet Trade Log
A1: ⚡ OPTIONS TRADE LOG
A2: Each row = one fill · Link partials & runners via Position ID · Set a Target Price to auto-calculate Planned R:R before you enter
A3: Chart Interval: | C3: 60 | D3: ← mins (60=1H · 240=4H · 15=15m)
A4: # | B4: Position ID | C4: Entry Date | D4: Entry Time | E4: Exit Date | F4: Exit Time | G4: Ticker | H4: Type (C/P) | I4: Strategy | J4: Strike ($) | K4: Expiry Date | L4: # Contracts | M4: Entry Price | N4: Fees ($) | O4: Exit Price | P4: Contract High | Q4: Premium Paid | R4: Premium Rcvd | S4: Max Value | T4: P&L ($) | U4: P&L (%) | V4: Max P&L ($) | W4: Max P&L (%) | X4: Planned R:R | Y4: Actual R:R | Z4: Max R:R | AA4: Days Held | AB4: Status | AC4: IV Rank | AD4: Notes | AE4: 📈 1H Chart | AF4: 📈 4H Chart
A5: =ROW()-4 -> 1 | Q5: =IF(L5="","",IF(M5<>"",M5*L5*100,IF(AND(O5<>"",B5<>""),IFERROR(AVERAGEIF($B$5:$B$1004,B5,$M$5:$M$1004)*L5*100,""),""))) | R5: =IF(AND(O5<>"",L5<>""),O5*L5*100,"") | S5: =IF(AND(P5<>"",L5<>""),P5*L5*100,"") | T5: =IF(AND(Q5<>"",R5<>""),R5-Q5,"") | U5: =IF(AND(Q5<>"",Q5<>0,T5<>""),T5/Q5,"") | V5: =IF(AND(S5<>"",Q5<>""),S5-Q5,"") | W5: =IF(AND(Q5<>"",Q5<>0,V5<>""),V5/Q5,"") | X5: "—" | Y5: =IF(AND(O5<>"",M5<>"",O5>M5),CONCATENATE("1 : ",TEXT((O5-M5)/M5,"0.00")),IF(AND(O5<>"",M5<>"",O5<M5),CONCATENATE("-1 : ",TEXT((M5-O5)/M5,"0.00")),"—")) -> — | Z5: =IF(AND(P5<>"",M5<>"",P5>M5),CONCATENATE("1 : ",TEXT((P5-M5)/M5,"0.00")),"—") -> — | AA5: =IF(AND(C5<>"",E5<>""),E5-C5,"") | AE5: =IF(G5<>"",HYPERLINK("https://www.tradingview.com/chart/?symbol="&G5&"&interval=60&from="&(AG5-10*3600)&"&to="&(AG5+50*3600),"📈 1H"),"") | AF5: =IF(G5<>"",HYPERLINK("https://www.tradingview.com/chart/?symbol="&G5&"&interval=240&from="&(AG5-10*14400)&"&to="&(AG5+50*14400),"📈 4H"),"") | AG5: =IF(C5<>"",INT((C5+IF(D5<>"",D5,0)-DATE(1970,1,1))*86400),"")
A6: =ROW()-4 -> 2 | Q6: =IF(L6="","",IF(M6<>"",M6*L6*100,IF(AND(O6<>"",B6<>""),IFERROR(AVERAGEIF($B$5:$B$1004,B6,$M$5:$M$1004)*L6*100,""),""))) | R6: =IF(AND(O6<>"",L6<>""),O6*L6*100,"") | S6: =IF(AND(P6<>"",L6<>""),P6*L6*100,"") | T6: =IF(AND(Q6<>"",R6<>""),R6-Q6,"") | U6: =IF(AND(Q6<>"",Q6<>0,T6<>""),T6/Q6,"") | V6: =IF(AND(S6<>"",Q6<>""),S6-Q6,"") | W6: =IF(AND(Q6<>"",Q6<>0,V6<>""),V6/Q6,"") | X6: "—" | Y6: =IF(AND(O6<>"",M6<>"",O6>M6),CONCATENATE("1 : ",TEXT((O6-M6)/M6,"0.00")),IF(AND(O6<>"",M6<>"",O6<M6),CONCATENATE("-1 : ",TEXT((M6-O6)/M6,"0.00")),"—")) -> — | Z6: =IF(AND(P6<>"",M6<>"",P6>M6),CONCATENATE("1 : ",TEXT((P6-M6)/M6,"0.00")),"—") -> — | AA6: =IF(AND(C6<>"",E6<>""),E6-C6,"") | AE6: =IF(G6<>"",HYPERLINK("https://www.tradingview.com/chart/?symbol="&G6&"&interval=60&from="&(AG6-10*3600)&"&to="&(AG6+50*3600),"📈 1H"),"") | AF6: =IF(G6<>"",HYPERLINK("https://www.tradingview.com/chart/?symbol="&G6&"&interval=240&from="&(AG6-10*14400)&"&to="&(AG6+50*14400),"📈 4H"),"") | AG6: =IF(C6<>"",INT((C6+IF(D6<>"",D6,0)-DATE(1970,1,1))*86400),"")
A7: =ROW()-4 -> 3 | Q7: =IF(L7="","",IF(M7<>"",M7*L7*100,IF(AND(O7<>"",B7<>""),IFERROR(AVERAGEIF($B$5:$B$1004,B7,$M$5:$M$1004)*L7*100,""),""))) | R7: =IF(AND(O7<>"",L7<>""),O7*L7*100,"") | S7: =IF(AND(P7<>"",L7<>""),P7*L7*100,"") | T7: =IF(AND(Q7<>"",R7<>""),R7-Q7,"") | U7: =IF(AND(Q7<>"",Q7<>0,T7<>""),T7/Q7,"") | V7: =IF(AND(S7<>"",Q7<>""),S7-Q7,"") | W7: =IF(AND(Q7<>"",Q7<>0,V7<>""),V7/Q7,"") | X7: "—" | Y7: =IF(AND(O7<>"",M7<>"",O7>M7),CONCATENATE("1 : ",TEXT((O7-M7)/M7,"0.00")),IF(AND(O7<>"",M7<>"",O7<M7),CONCATENATE("-1 : ",TEXT((M7-O7)/M7,"0.00")),"—")) -> — | Z7: =IF(AND(P7<>"",M7<>"",P7>M7),CONCATENATE("1 : ",TEXT((P7-M7)/M7,"0.00")),"—") -> — | AA7: =IF(AND(C7<>"",E7<>""),E7-C7,"") | AE7: =IF(G7<>"",HYPERLINK("https://www.tradingview.com/chart/?symbol="&G7&"&interval=60&from="&(AG7-10*3600)&"&to="&(AG7+50*3600),"📈 1H"),"") | AF7: =IF(G7<>"",HYPERLINK("https://www.tradingview.com/chart/?symbol="&G7&"&interval=240&from="&(AG7-10*14400)&"&to="&(AG7+50*14400),"📈 4H"),"") | AG7: =IF(C7<>"",INT((C7+IF(D7<>"",D7,0)-DATE(1970,1,1))*86400),"")
A8: =ROW()-4 -> 4 | Q8: =IF(L8="","",IF(M8<>"",M8*L8*100,IF(AND(O8<>"",B8<>""),IFERROR(AVERAGEIF($B$5:$B$1004,B8,$M$5:$M$1004)*L8*100,""),""))) | R8: =IF(AND(O8<>"",L8<>""),O8*L8*100,"") | S8: =IF(AND(P8<>"",L8<>""),P8*L8*100,"") | T8: =IF(AND(Q8<>"",R8<>""),R8-Q8,"") | U8: =IF(AND(Q8<>"",Q8<>0,T8<>""),T8/Q8,"") | V8: =IF(AND(S8<>"",Q8<>""),S8-Q8,"") | W8: =IF(AND(Q8<>"",Q8<>0,V8<>""),V8/Q8,"") | X8: "—" | Y8: =IF(AND(O8<>"",M8<>"",O8>M8),CONCATENATE("1 : ",TEXT((O8-M8)/M8,"0.00")),IF(AND(O8<>"",M8<>"",O8<M8),CONCATENATE("-1 : ",TEXT((M8-O8)/M8,"0.00")),"—")) -> — | Z8: =IF(AND(P8<>"",M8<>"",P8>M8),CONCATENATE("1 : ",TEXT((P8-M8)/M8,"0.00")),"—") -> — | AA8: =IF(AND(C8<>"",E8<>""),E8-C8,"") | AE8: =IF(G8<>"",HYPERLINK("https://www.tradingview.com/chart/?symbol="&G8&"&interval=60&from="&(AG8-10*3600)&"&to="&(AG8+50*3600),"📈 1H"),"") | AF8: =IF(G8<>"",HYPERLINK("https://www.tradingview.com/chart/?symbol="&G8&"&interval=240&from="&(AG8-10*14400)&"&to="&(AG8+50*14400),"📈 4H"),"") | AG8: =IF(C8<>"",INT((C8+IF(D8<>"",D8,0)-DATE(1970,1,1))*86400),"")
A9: =ROW()-4 -> 5 | Q9: =IF(L9="","",IF(M9<>"",M9*L9*100,IF(AND(O9<>"",B9<>""),IFERROR(AVERAGEIF($B$5:$B$1004,B9,$M$5:$M$1004)*L9*100,""),""))) | R9: =IF(AND(O9<>"",L9<>""),O9*L9*100,"") | S9: =IF(AND(P9<>"",L9<>""),P9*L9*100,"") | T9: =IF(AND(Q9<>"",R9<>""),R9-Q9,"") | U9: =IF(AND(Q9<>"",Q9<>0,T9<>""),T9/Q9,"") | V9: =IF(AND(S9<>"",Q9<>""),S9-Q9,"") | W9: =IF(AND(Q9<>"",Q9<>0,V9<>""),V9/Q9,"") | X9: "—" | Y9: =IF(AND(O9<>"",M9<>"",O9>M9),CONCATENATE("1 : ",TEXT((O9-M9)/M9,"0.00")),IF(AND(O9<>"",M9<>"",O9<M9),CONCATENATE("-1 : ",TEXT((M9-O9)/M9,"0.00")),"—")) -> — | Z9: =IF(AND(P9<>"",M9<>"",P9>M9),CONCATENATE("1 : ",TEXT((P9-M9)/M9,"0.00")),"—") -> — | AA9: =IF(AND(C9<>"",E9<>""),E9-C9,"") | AE9: =IF(G9<>"",HYPERLINK("https://www.tradingview.com/chart/?symbol="&G9&"&interval=60&from="&(AG9-10*3600)&"&to="&(AG9+50*3600),"📈 1H"),"") | AF9: =IF(G9<>"",HYPERLINK("https://www.tradingview.com/chart/?symbol="&G9&"&interval=240&from="&(AG9-10*14400)&"&to="&(AG9+50*14400),"📈 4H"),"") | AG9: =IF(C9<>"",INT((C9+IF(D9<>"",D9,0)-DATE(1970,1,1))*86400),"")
A10: =ROW()-4 -> 6 | Q10: =IF(L10="","",IF(M10<>"",M10*L10*100,IF(AND(O10<>"",B10<>""),IFERROR(AVERAGEIF($B$5:$B$1004,B10,$M$5:$M$1004)*L10*100,""),""))) | R10: =IF(AND(O10<>"",L10<>""),O10*L10*100,"") | S10: =IF(AND(P10<>"",L10<>""),P10*L10*100,"") | T10: =IF(AND(Q10<>"",R10<>""),R10-Q10,"") | U10: =IF(AND(Q10<>"",Q10<>0,T10<>""),T10/Q10,"") | V10: =IF(AND(S10<>"",Q10<>""),S10-Q10,"") | W10: =IF(AND(Q10<>"",Q10<>0,V10<>""),V10/Q10,"") | X10: "—" | Y10: =IF(AND(O10<>"",M10<>"",O10>M10),CONCATENATE("1 : ",TEXT((O10-M10)/M10,"0.00")),IF(AND(O10<>"",M10<>"",O10<M10),CONCATENATE("-1 : ",TEXT((M10-O10)/M10,"0.00")),"—")) -> — | Z10: =IF(AND(P10<>"",M10<>"",P10>M10),CONCATENATE("1 : ",TEXT((P10-M10)/M10,"0.00")),"—") -> — | AA10: =IF(AND(C10<>"",E10<>""),E10-C10,"") | AE10: =IF(G10<>"",HYPERLINK("https://www.tradingview.com/chart/?symbol="&G10&"&interval=60&from="&(AG10-10*3600)&"&to="&(AG10+50*3600),"📈 1H"),"") | AF10: =IF(G10<>"",HYPERLINK("https://www.tradingview.com/chart/?symbol="&G10&"&interval=240&from="&(AG10-10*14400)&"&to="&(AG10+50*14400),"📈 4H"),"") | AG10: =IF(C10<>"",INT((C10+IF(D10<>"",D10,0)-DATE(1970,1,1))*86400),"")
A11: =ROW()-4 -> 7 | Q11: =IF(L11="","",IF(M11<>"",M11*L11*100,IF(AND(O11<>"",B11<>""),IFERROR(AVERAGEIF($B$5:$B$1004,B11,$M$5:$M$1004)*L11*100,""),""))) | R11: =IF(AND(O11<>"",L11<>""),O11*L11*100,"") | S11: =IF(AND(P11<>"",L11<>""),P11*L11*100,"") | T11: =IF(AND(Q11<>"",R11<>""),R11-Q11,"") | U11: =IF(AND(Q11<>"",Q11<>0,T11<>""),T11/Q11,"") | V11: =IF(AND(S11<>"",Q11<>""),S11-Q11,"") | W11: =IF(AND(Q11<>"",Q11<>0,V11<>""),V11/Q11,"") | X11: "—" | Y11: =IF(AND(O11<>"",M11<>"",O11>M11),CONCATENATE("1 : ",TEXT((O11-M11)/M11,"0.00")),IF(AND(O11<>"",M11<>"",O11<M11),CONCATENATE("-1 : ",TEXT((M11-O11)/M11,"0.00")),"—")) -> — | Z11: =IF(AND(P11<>"",M11<>"",P11>M11),CONCATENATE("1 : ",TEXT((P11-M11)/M11,"0.00")),"—") -> — | AA11: =IF(AND(C11<>"",E11<>""),E11-C11,"") | AE11: =IF(G11<>"",HYPERLINK("https://www.tradingview.com/chart/?symbol="&G11&"&interval=60&from="&(AG11-10*3600)&"&to="&(AG11+50*3600),"📈 1H"),"") | AF11: =IF(G11<>"",HYPERLINK("https://www.tradingview.com/chart/?symbol="&G11&"&interval=240&from="&(AG11-10*14400)&"&to="&(AG11+50*14400),"📈 4H"),"") | AG11: =IF(C11<>"",INT((C11+IF(D11<>"",D11,0)-DATE(1970,1,1))*86400),"")
A12: =ROW()-4 -> 8 | Q12: =IF(L12="","",IF(M12<>"",M12*L12*100,IF(AND(O12<>"",B12<>""),IFERROR(AVERAGEIF($B$5:$B$1004,B12,$M$5:$M$1004)*L12*100,""),""))) | R12: =IF(AND(O12<>"",L12<>""),O12*L12*100,"") | S12: =IF(AND(P12<>"",L12<>""),P12*L12*100,"") | T12: =IF(AND(Q12<>"",R12<>""),R12-Q12,"") | U12: =IF(AND(Q12<>"",Q12<>0,T12<>""),T12/Q12,"") | V12: =IF(AND(S12<>"",Q12<>""),S12-Q12,"") | W12: =IF(AND(Q12<>"",Q12<>0,V12<>""),V12/Q12,"") | X12: "—" | Y12: =IF(AND(O12<>"",M12<>"",O12>M12),CONCATENATE("1 : ",TEXT((O12-M12)/M12,"0.00")),IF(AND(O12<>"",M12<>"",O12<M12),CONCATENATE("-1 : ",TEXT((M12-O12)/M12,"0.00")),"—")) -> — | Z12: =IF(AND(P12<>"",M12<>"",P12>M12),CONCATENATE("1 : ",TEXT((P12-M12)/M12,"0.00")),"—") -> — | AA12: =IF(AND(C12<>"",E12<>""),E12-C12,"") | AE12: =IF(G12<>"",HYPERLINK("https://www.tradingview.com/chart/?symbol="&G12&"&interval=60&from="&(AG12-10*3600)&"&to="&(AG12+50*3600),"📈 1H"),"") | AF12: =IF(G12<>"",HYPERLINK("https://www.tradingview.com/chart/?symbol="&G12&"&interval=240&from="&(AG12-10*14400)&"&to="&(AG12+50*14400),"📈 4H"),"") | AG12: =IF(C12<>"",INT((C12+IF(D12<>"",D12,0)-DATE(1970,1,1))*86400),"")
A13: =ROW()-4 -> 9 | Q13: =IF(L13="","",IF(M13<>"",M13*L13*100,IF(AND(O13<>"",B13<>""),IFERROR(AVERAGEIF($B$5:$B$1004,B13,$M$5:$M$1004)*L13*100,""),""))) | R13: =IF(AND(O13<>"",L13<>""),O13*L13*100,"") | S13: =IF(AND(P13<>"",L13<>""),P13*L13*100,"") | T13: =IF(AND(Q13<>"",R13<>""),R13-Q13,"") | U13: =IF(AND(Q13<>"",Q13<>0,T13<>""),T13/Q13,"") | V13: =IF(AND(S13<>"",Q13<>""),S13-Q13,"") | W13: =IF(AND(Q13<>"",Q13<>0,V13<>""),V13/Q13,"") | X13: "—" | Y13: =IF(AND(O13<>"",M13<>"",O13>M13),CONCATENATE("1 : ",TEXT((O13-M13)/M13,"0.00")),IF(AND(O13<>"",M13<>"",O13<M13),CONCATENATE("-1 : ",TEXT((M13-O13)/M13,"0.00")),"—")) -> — | Z13: =IF(AND(P13<>"",M13<>"",P13>M13),CONCATENATE("1 : ",TEXT((P13-M13)/M13,"0.00")),"—") -> — | AA13: =IF(AND(C13<>"",E13<>""),E13-C13,"") | AE13: =IF(G13<>"",HYPERLINK("https://www.tradingview.com/chart/?symbol="&G13&"&interval=60&from="&(AG13-10*3600)&"&to="&(AG13+50*3600),"📈 1H"),"") | AF13: =IF(G13<>"",HYPERLINK("https://www.tradingview.com/chart/?symbol="&G13&"&interval=240&from="&(AG13-10*14400)&"&to="&(AG13+50*14400),"📈 4H"),"") | AG13: =IF(C13<>"",INT((C13+IF(D13<>"",D13,0)-DATE(1970,1,1))*86400),"")
A14: =ROW()-4 -> 10 | Q14: =IF(L14="","",IF(M14<>"",M14*L14*100,IF(AND(O14<>"",B14<>""),IFERROR(AVERAGEIF($B$5:$B$1004,B14,$M$5:$M$1004)*L14*100,""),""))) | R14: =IF(AND(O14<>"",L14<>""),O14*L14*100,"") | S14: =IF(AND(P14<>"",L14<>""),P14*L14*100,"") | T14: =IF(AND(Q14<>"",R14<>""),R14-Q14,"") | U14: =IF(AND(Q14<>"",Q14<>0,T14<>""),T14/Q14,"") | V14: =IF(AND(S14<>"",Q14<>""),S14-Q14,"") | W14: =IF(AND(Q14<>"",Q14<>0,V14<>""),V14/Q14,"") | X14: "—" | Y14: =IF(AND(O14<>"",M14<>"",O14>M14),CONCATENATE("1 : ",TEXT((O14-M14)/M14,"0.00")),IF(AND(O14<>"",M14<>"",O14<M14),CONCATENATE("-1 : ",TEXT((M14-O14)/M14,"0.00")),"—")) -> — | Z14: =IF(AND(P14<>"",M14<>"",P14>M14),CONCATENATE("1 : ",TEXT((P14-M14)/M14,"0.00")),"—") -> — | AA14: =IF(AND(C14<>"",E14<>""),E14-C14,"") | AE14: =IF(G14<>"",HYPERLINK("https://www.tradingview.com/chart/?symbol="&G14&"&interval=60&from="&(AG14-10*3600)&"&to="&(AG14+50*3600),"📈 1H"),"") | AF14: =IF(G14<>"",HYPERLINK("https://www.tradingview.com/chart/?symbol="&G14&"&interval=240&from="&(AG14-10*14400)&"&to="&(AG14+50*14400),"📈 4H"),"") | AG14: =IF(C14<>"",INT((C14+IF(D14<>"",D14,0)-DATE(1970,1,1))*86400),"")
A15: =ROW()-4 -> 11 | Q15: =IF(L15="","",IF(M15<>"",M15*L15*100,IF(AND(O15<>"",B15<>""),IFERROR(AVERAGEIF($B$5:$B$1004,B15,$M$5:$M$1004)*L15*100,""),""))) | R15: =IF(AND(O15<>"",L15<>""),O15*L15*100,"") | S15: =IF(AND(P15<>"",L15<>""),P15*L15*100,"") | T15: =IF(AND(Q15<>"",R15<>""),R15-Q15,"") | U15: =IF(AND(Q15<>"",Q15<>0,T15<>""),T15/Q15,"") | V15: =IF(AND(S15<>"",Q15<>""),S15-Q15,"") | W15: =IF(AND(Q15<>"",Q15<>0,V15<>""),V15/Q15,"") | X15: "—" | Y15: =IF(AND(O15<>"",M15<>"",O15>M15),CONCATENATE("1 : ",TEXT((O15-M15)/M15,"0.00")),IF(AND(O15<>"",M15<>"",O15<M15),CONCATENATE("-1 : ",TEXT((M15-O15)/M15,"0.00")),"—")) -> — | Z15: =IF(AND(P15<>"",M15<>"",P15>M15),CONCATENATE("1 : ",TEXT((P15-M15)/M15,"0.00")),"—") -> — | AA15: =IF(AND(C15<>"",E15<>""),E15-C15,"") | AE15: =IF(G15<>"",HYPERLINK("https://www.tradingview.com/chart/?symbol="&G15&"&interval=60&from="&(AG15-10*3600)&"&to="&(AG15+50*3600),"📈 1H"),"") | AF15: =IF(G15<>"",HYPERLINK("https://www.tradingview.com/chart/?symbol="&G15&"&interval=240&from="&(AG15-10*14400)&"&to="&(AG15+50*14400),"📈 4H"),"") | AG15: =IF(C15<>"",INT((C15+IF(D15<>"",D15,0)-DATE(1970,1,1))*86400),"")
A16: =ROW()-4 -> 12 | Q16: =IF(L16="","",IF(M16<>"",M16*L16*100,IF(AND(O16<>"",B16<>""),IFERROR(AVERAGEIF($B$5:$B$1004,B16,$M$5:$M$1004)*L16*100,""),""))) | R16: =IF(AND(O16<>"",L16<>""),O16*L16*100,"") | S16: =IF(AND(P16<>"",L16<>""),P16*L16*100,"") | T16: =IF(AND(Q16<>"",R16<>""),R16-Q16,"") | U16: =IF(AND(Q16<>"",Q16<>0,T16<>""),T16/Q16,"") | V16: =IF(AND(S16<>"",Q16<>""),S16-Q16,"") | W16: =IF(AND(Q16<>"",Q16<>0,V16<>""),V16/Q16,"") | X16: "—" | Y16: =IF(AND(O16<>"",M16<>"",O16>M16),CONCATENATE("1 : ",TEXT((O16-M16)/M16,"0.00")),IF(AND(O16<>"",M16<>"",O16<M16),CONCATENATE("-1 : ",TEXT((M16-O16)/M16,"0.00")),"—")) -> — | Z16: =IF(AND(P16<>"",M16<>"",P16>M16),CONCATENATE("1 : ",TEXT((P16-M16)/M16,"0.00")),"—") -> — | AA16: =IF(AND(C16<>"",E16<>""),E16-C16,"") | AE16: =IF(G16<>"",HYPERLINK("https://www.tradingview.com/chart/?symbol="&G16&"&interval=60&from="&(AG16-10*3600)&"&to="&(AG16+50*3600),"📈 1H"),"") | AF16: =IF(G16<>"",HYPERLINK("https://www.tradingview.com/chart/?symbol="&G16&"&interval=240&from="&(AG16-10*14400)&"&to="&(AG16+50*14400),"📈 4H"),"") | AG16: =IF(C16<>"",INT((C16+IF(D16<>"",D16,0)-DATE(1970,1,1))*86400),"")
... A1004: =ROW()-4 -> 1000 | Q1004: =IF(L1004="","",IF(M1004<>"",M1004*L1004*100,IF(AND(O1004<>"",B1004<>""),IFERROR(AVERAGEIF($B$5:$B$1004,B1004,$M$5:$M$1004)*L1004*100,""),""))) | R1004: =IF(AND(O1004<>"",L1004<>""),O1004*L1004*100,"") | S1004: =IF(AND(P1004<>"",L1004<>""),P1004*L1004*100,"") | T1004: =IF(AND(Q1004<>"",R1004<>""),R1004-Q1004,"") | U1004: =IF(AND(Q1004<>"",Q1004<>0,T1004<>""),T1004/Q1004,"") | V1004: =IF(AND(S1004<>"",Q1004<>""),S1004-Q1004,"") | W1004: =IF(AND(Q1004<>"",Q1004<>0,V1004<>""),V1004/Q1004,"") | X1004: "—" | Y1004: =IF(AND(O1004<>"",M1004<>"",O1004>M1004),CONCATENATE("1 : ",TEXT((O1004-M1004)/M1004,"0.00")),IF(AND(O1004<>"",M1004<>"",O1004<M1004),CONCATENATE("-1 : ",TEXT((M1004-O1004)/M1004,"0.00")),"—")) -> — | Z1004: =IF(AND(P1004<>"",M1004<>"",P1004>M1004),CONCATENATE("1 : ",TEXT((P1004-M1004)/M1004,"0.00")),"—") -> — | AA1004: =IF(AND(C1004<>"",E1004<>""),E1004-C1004,"") | AE1004: =IF(G1004<>"",HYPERLINK("https://www.tradingview.com/chart/?symbol="&G1004&"&interval=60&from="&(AG1004-10*3600)&"&to="&(AG1004+50*3600),"📈 1H"),"") | AF1004: =IF(G1004<>"",HYPERLINK("https://www.tradingview.com/chart/?symbol="&G1004&"&interval=240&from="&(AG1004-10*14400)&"&to="&(AG1004+50*14400),"📈 4H"),"") | AG1004: =IF(C1004<>"",INT((C1004+IF(D1004<>"",D1004,0)-DATE(1970,1,1))*86400),"")
A1006: 🟡 Position ID = shared key for partials/runners | 🔵 Teal = Target Price & Planned R:R | 🟣 Purple = Max cols | R:R shown as '1 : X' (reward per $1 risked) | Negative Actual R:R shown as '-1 : X' (loss trade)

Sheet Position Summary
A1: 📋 POSITION SUMMARY
A2: Rolls up all rows sharing the same Position ID — partials + runners combined into one P&L
A3: 💡 In Google Sheets: Position IDs auto-populate via UNIQUE(). In Excel, type Position IDs manually in column A.
A4: Position ID | B4: Ticker | C4: Strategy | D4: # Fills | E4: Total Contracts | F4: Total Prem. Paid | G4: Total Prem. Rcvd | H4: Total P&L ($) | I4: Total P&L (%) | J4: Total Max P&L ($) | K4: Total Max P&L (%) | L4: Open Contracts | M4: Status
A5: =IFERROR(unique(filter('Trade Log'!B5:B1004,'Trade Log'!B5:B1004<>"")),"") | B5: =IF(A5<>"",IFERROR(INDEX('Trade Log'!$G$5:$G$1004,MATCH(A5,'Trade Log'!$B$5:$B$1004,0)),""),"") | C5: =IF(A5<>"",IFERROR(INDEX('Trade Log'!$I$5:$I$1004,MATCH(A5,'Trade Log'!$B$5:$B$1004,0)),""),"") | D5: =IF(A5<>"",COUNTIF('Trade Log'!$B$5:$B$1004,A5),"") | E5: =IF(A5<>"",SUMIF('Trade Log'!$B$5:$B$1004,A5,'Trade Log'!$L$5:$L$1004),"") | F5: =IF(A5<>"",SUMIF('Trade Log'!$B$5:$B$1004,A5,'Trade Log'!$Q$5:$Q$1004),"") | G5: =IF(A5<>"",SUMIF('Trade Log'!$B$5:$B$1004,A5,'Trade Log'!$R$5:$R$1004),"") | H5: =IF(A5<>"",SUMIF('Trade Log'!$B$5:$B$1004,A5,'Trade Log'!$T$5:$T$1004),"") | I5: =IF(A5<>"",IFERROR(SUMIF('Trade Log'!$B$5:$B$1004,A5,'Trade Log'!$R$5:$R$1004)/SUMIF('Trade Log'!$B$5:$B$1004,A5,'Trade Log'!$Q$5:$Q$1004)-1,""),"") | J5: =IF(A5<>"",SUMIF('Trade Log'!$B$5:$B$1004,A5,'Trade Log'!$V$5:$V$1004),"") | K5: =IF(A5<>"",IFERROR(SUMIF('Trade Log'!$B$5:$B$1004,A5,'Trade Log'!$V$5:$V$1004)/SUMIF('Trade Log'!$B$5:$B$1004,A5,'Trade Log'!$Q$5:$Q$1004),""),"") | L5: =IF(A5<>"",IFERROR(SUMIFS('Trade Log'!$L$5:$L$1004,'Trade Log'!$B$5:$B$1004,A5,'Trade Log'!$E$5:$E$1004,""),0),"") | M5: =IF(A5<>"",IFERROR(INDEX('Trade Log'!$AB$5:$AB$1004,MATCH(2,1/('Trade Log'!$B$5:$B$1004=A5),1)),""),"")
B6: =IF(A6<>"",IFERROR(INDEX('Trade Log'!$G$5:$G$1004,MATCH(A6,'Trade Log'!$B$5:$B$1004,0)),""),"") | C6: =IF(A6<>"",IFERROR(INDEX('Trade Log'!$I$5:$I$1004,MATCH(A6,'Trade Log'!$B$5:$B$1004,0)),""),"") | D6: =IF(A6<>"",COUNTIF('Trade Log'!$B$5:$B$1004,A6),"") | E6: =IF(A6<>"",SUMIF('Trade Log'!$B$5:$B$1004,A6,'Trade Log'!$L$5:$L$1004),"") | F6: =IF(A6<>"",SUMIF('Trade Log'!$B$5:$B$1004,A6,'Trade Log'!$Q$5:$Q$1004),"") | G6: =IF(A6<>"",SUMIF('Trade Log'!$B$5:$B$1004,A6,'Trade Log'!$R$5:$R$1004),"") | H6: =IF(A6<>"",SUMIF('Trade Log'!$B$5:$B$1004,A6,'Trade Log'!$T$5:$T$1004),"") | I6: =IF(A6<>"",IFERROR(SUMIF('Trade Log'!$B$5:$B$1004,A6,'Trade Log'!$R$5:$R$1004)/SUMIF('Trade Log'!$B$5:$B$1004,A6,'Trade Log'!$Q$5:$Q$1004)-1,""),"") | J6: =IF(A6<>"",SUMIF('Trade Log'!$B$5:$B$1004,A6,'Trade Log'!$V$5:$V$1004),"") | K6: =IF(A6<>"",IFERROR(SUMIF('Trade Log'!$B$5:$B$1004,A6,'Trade Log'!$V$5:$V$1004)/SUMIF('Trade Log'!$B$5:$B$1004,A6,'Trade Log'!$Q$5:$Q$1004),""),"") | L6: =IF(A6<>"",IFERROR(SUMIFS('Trade Log'!$L$5:$L$1004,'Trade Log'!$B$5:$B$1004,A6,'Trade Log'!$E$5:$E$1004,""),0),"") | M6: =IF(A6<>"",IFERROR(INDEX('Trade Log'!$AB$5:$AB$1004,MATCH(2,1/('Trade Log'!$B$5:$B$1004=A6),1)),""),"")
B7: =IF(A7<>"",IFERROR(INDEX('Trade Log'!$G$5:$G$1004,MATCH(A7,'Trade Log'!$B$5:$B$1004,0)),""),"") | C7: =IF(A7<>"",IFERROR(INDEX('Trade Log'!$I$5:$I$1004,MATCH(A7,'Trade Log'!$B$5:$B$1004,0)),""),"") | D7: =IF(A7<>"",COUNTIF('Trade Log'!$B$5:$B$1004,A7),"") | E7: =IF(A7<>"",SUMIF('Trade Log'!$B$5:$B$1004,A7,'Trade Log'!$L$5:$L$1004),"") | F7: =IF(A7<>"",SUMIF('Trade Log'!$B$5:$B$1004,A7,'Trade Log'!$Q$5:$Q$1004),"") | G7: =IF(A7<>"",SUMIF('Trade Log'!$B$5:$B$1004,A7,'Trade Log'!$R$5:$R$1004),"") | H7: =IF(A7<>"",SUMIF('Trade Log'!$B$5:$B$1004,A7,'Trade Log'!$T$5:$T$1004),"") | I7: =IF(A7<>"",IFERROR(SUMIF('Trade Log'!$B$5:$B$1004,A7,'Trade Log'!$R$5:$R$1004)/SUMIF('Trade Log'!$B$5:$B$1004,A7,'Trade Log'!$Q$5:$Q$1004)-1,""),"") | J7: =IF(A7<>"",SUMIF('Trade Log'!$B$5:$B$1004,A7,'Trade Log'!$V$5:$V$1004),"") | K7: =IF(A7<>"",IFERROR(SUMIF('Trade Log'!$B$5:$B$1004,A7,'Trade Log'!$V$5:$V$1004)/SUMIF('Trade Log'!$B$5:$B$1004,A7,'Trade Log'!$Q$5:$Q$1004),""),"") | L7: =IF(A7<>"",IFERROR(SUMIFS('Trade Log'!$L$5:$L$1004,'Trade Log'!$B$5:$B$1004,A7,'Trade Log'!$E$5:$E$1004,""),0),"") | M7: =IF(A7<>"",IFERROR(INDEX('Trade Log'!$AB$5:$AB$1004,MATCH(2,1/('Trade Log'!$B$5:$B$1004=A7),1)),""),"")
B8: =IF(A8<>"",IFERROR(INDEX('Trade Log'!$G$5:$G$1004,MATCH(A8,'Trade Log'!$B$5:$B$1004,0)),""),"") | C8: =IF(A8<>"",IFERROR(INDEX('Trade Log'!$I$5:$I$1004,MATCH(A8,'Trade Log'!$B$5:$B$1004,0)),""),"") | D8: =IF(A8<>"",COUNTIF('Trade Log'!$B$5:$B$1004,A8),"") | E8: =IF(A8<>"",SUMIF('Trade Log'!$B$5:$B$1004,A8,'Trade Log'!$L$5:$L$1004),"") | F8: =IF(A8<>"",SUMIF('Trade Log'!$B$5:$B$1004,A8,'Trade Log'!$Q$5:$Q$1004),"") | G8: =IF(A8<>"",SUMIF('Trade Log'!$B$5:$B$1004,A8,'Trade Log'!$R$5:$R$1004),"") | H8: =IF(A8<>"",SUMIF('Trade Log'!$B$5:$B$1004,A8,'Trade Log'!$T$5:$T$1004),"") | I8: =IF(A8<>"",IFERROR(SUMIF('Trade Log'!$B$5:$B$1004,A8,'Trade Log'!$R$5:$R$1004)/SUMIF('Trade Log'!$B$5:$B$1004,A8,'Trade Log'!$Q$5:$Q$1004)-1,""),"") | J8: =IF(A8<>"",SUMIF('Trade Log'!$B$5:$B$1004,A8,'Trade Log'!$V$5:$V$1004),"") | K8: =IF(A8<>"",IFERROR(SUMIF('Trade Log'!$B$5:$B$1004,A8,'Trade Log'!$V$5:$V$1004)/SUMIF('Trade Log'!$B$5:$B$1004,A8,'Trade Log'!$Q$5:$Q$1004),""),"") | L8: =IF(A8<>"",IFERROR(SUMIFS('Trade Log'!$L$5:$L$1004,'Trade Log'!$B$5:$B$1004,A8,'Trade Log'!$E$5:$E$1004,""),0),"") | M8: =IF(A8<>"",IFERROR(INDEX('Trade Log'!$AB$5:$AB$1004,MATCH(2,1/('Trade Log'!$B$5:$B$1004=A8),1)),""),"")
B9: =IF(A9<>"",IFERROR(INDEX('Trade Log'!$G$5:$G$1004,MATCH(A9,'Trade Log'!$B$5:$B$1004,0)),""),"") | C9: =IF(A9<>"",IFERROR(INDEX('Trade Log'!$I$5:$I$1004,MATCH(A9,'Trade Log'!$B$5:$B$1004,0)),""),"") | D9: =IF(A9<>"",COUNTIF('Trade Log'!$B$5:$B$1004,A9),"") | E9: =IF(A9<>"",SUMIF('Trade Log'!$B$5:$B$1004,A9,'Trade Log'!$L$5:$L$1004),"") | F9: =IF(A9<>"",SUMIF('Trade Log'!$B$5:$B$1004,A9,'Trade Log'!$Q$5:$Q$1004),"") | G9: =IF(A9<>"",SUMIF('Trade Log'!$B$5:$B$1004,A9,'Trade Log'!$R$5:$R$1004),"") | H9: =IF(A9<>"",SUMIF('Trade Log'!$B$5:$B$1004,A9,'Trade Log'!$T$5:$T$1004),"") | I9: =IF(A9<>"",IFERROR(SUMIF('Trade Log'!$B$5:$B$1004,A9,'Trade Log'!$R$5:$R$1004)/SUMIF('Trade Log'!$B$5:$B$1004,A9,'Trade Log'!$Q$5:$Q$1004)-1,""),"") | J9: =IF(A9<>"",SUMIF('Trade Log'!$B$5:$B$1004,A9,'Trade Log'!$V$5:$V$1004),"") | K9: =IF(A9<>"",IFERROR(SUMIF('Trade Log'!$B$5:$B$1004,A9,'Trade Log'!$V$5:$V$1004)/SUMIF('Trade Log'!$B$5:$B$1004,A9,'Trade Log'!$Q$5:$Q$1004),""),"") | L9: =IF(A9<>"",IFERROR(SUMIFS('Trade Log'!$L$5:$L$1004,'Trade Log'!$B$5:$B$1004,A9,'Trade Log'!$E$5:$E$1004,""),0),"") | M9: =IF(A9<>"",IFERROR(INDEX('Trade Log'!$AB$5:$AB$1004,MATCH(2,1/('Trade Log'!$B$5:$B$1004=A9),1)),""),"")
B10: =IF(A10<>"",IFERROR(INDEX('Trade Log'!$G$5:$G$1004,MATCH(A10,'Trade Log'!$B$5:$B$1004,0)),""),"") | C10: =IF(A10<>"",IFERROR(INDEX('Trade Log'!$I$5:$I$1004,MATCH(A10,'Trade Log'!$B$5:$B$1004,0)),""),"") | D10: =IF(A10<>"",COUNTIF('Trade Log'!$B$5:$B$1004,A10),"") | E10: =IF(A10<>"",SUMIF('Trade Log'!$B$5:$B$1004,A10,'Trade Log'!$L$5:$L$1004),"") | F10: =IF(A10<>"",SUMIF('Trade Log'!$B$5:$B$1004,A10,'Trade Log'!$Q$5:$Q$1004),"") | G10: =IF(A10<>"",SUMIF('Trade Log'!$B$5:$B$1004,A10,'Trade Log'!$R$5:$R$1004),"") | H10: =IF(A10<>"",SUMIF('Trade Log'!$B$5:$B$1004,A10,'Trade Log'!$T$5:$T$1004),"") | I10: =IF(A10<>"",IFERROR(SUMIF('Trade Log'!$B$5:$B$1004,A10,'Trade Log'!$R$5:$R$1004)/SUMIF('Trade Log'!$B$5:$B$1004,A10,'Trade Log'!$Q$5:$Q$1004)-1,""),"") | J10: =IF(A10<>"",SUMIF('Trade Log'!$B$5:$B$1004,A10,'Trade Log'!$V$5:$V$1004),"") | K10: =IF(A10<>"",IFERROR(SUMIF('Trade Log'!$B$5:$B$1004,A10,'Trade Log'!$V$5:$V$1004)/SUMIF('Trade Log'!$B$5:$B$1004,A10,'Trade Log'!$Q$5:$Q$1004),""),"") | L10: =IF(A10<>"",IFERROR(SUMIFS('Trade Log'!$L$5:$L$1004,'Trade Log'!$B$5:$B$1004,A10,'Trade Log'!$E$5:$E$1004,""),0),"") | M10: =IF(A10<>"",IFERROR(INDEX('Trade Log'!$AB$5:$AB$1004,MATCH(2,1/('Trade Log'!$B$5:$B$1004=A10),1)),""),"")
B11: =IF(A11<>"",IFERROR(INDEX('Trade Log'!$G$5:$G$1004,MATCH(A11,'Trade Log'!$B$5:$B$1004,0)),""),"") | C11: =IF(A11<>"",IFERROR(INDEX('Trade Log'!$I$5:$I$1004,MATCH(A11,'Trade Log'!$B$5:$B$1004,0)),""),"") | D11: =IF(A11<>"",COUNTIF('Trade Log'!$B$5:$B$1004,A11),"") | E11: =IF(A11<>"",SUMIF('Trade Log'!$B$5:$B$1004,A11,'Trade Log'!$L$5:$L$1004),"") | F11: =IF(A11<>"",SUMIF('Trade Log'!$B$5:$B$1004,A11,'Trade Log'!$Q$5:$Q$1004),"") | G11: =IF(A11<>"",SUMIF('Trade Log'!$B$5:$B$1004,A11,'Trade Log'!$R$5:$R$1004),"") | H11: =IF(A11<>"",SUMIF('Trade Log'!$B$5:$B$1004,A11,'Trade Log'!$T$5:$T$1004),"") | I11: =IF(A11<>"",IFERROR(SUMIF('Trade Log'!$B$5:$B$1004,A11,'Trade Log'!$R$5:$R$1004)/SUMIF('Trade Log'!$B$5:$B$1004,A11,'Trade Log'!$Q$5:$Q$1004)-1,""),"") | J11: =IF(A11<>"",SUMIF('Trade Log'!$B$5:$B$1004,A11,'Trade Log'!$V$5:$V$1004),"") | K11: =IF(A11<>"",IFERROR(SUMIF('Trade Log'!$B$5:$B$1004,A11,'Trade Log'!$V$5:$V$1004)/SUMIF('Trade Log'!$B$5:$B$1004,A11,'Trade Log'!$Q$5:$Q$1004),""),"") | L11: =IF(A11<>"",IFERROR(SUMIFS('Trade Log'!$L$5:$L$1004,'Trade Log'!$B$5:$B$1004,A11,'Trade Log'!$E$5:$E$1004,""),0),"") | M11: =IF(A11<>"",IFERROR(INDEX('Trade Log'!$AB$5:$AB$1004,MATCH(2,1/('Trade Log'!$B$5:$B$1004=A11),1)),""),"")
B12: =IF(A12<>"",IFERROR(INDEX('Trade Log'!$G$5:$G$1004,MATCH(A12,'Trade Log'!$B$5:$B$1004,0)),""),"") | C12: =IF(A12<>"",IFERROR(INDEX('Trade Log'!$I$5:$I$1004,MATCH(A12,'Trade Log'!$B$5:$B$1004,0)),""),"") | D12: =IF(A12<>"",COUNTIF('Trade Log'!$B$5:$B$1004,A12),"") | E12: =IF(A12<>"",SUMIF('Trade Log'!$B$5:$B$1004,A12,'Trade Log'!$L$5:$L$1004),"") | F12: =IF(A12<>"",SUMIF('Trade Log'!$B$5:$B$1004,A12,'Trade Log'!$Q$5:$Q$1004),"") | G12: =IF(A12<>"",SUMIF('Trade Log'!$B$5:$B$1004,A12,'Trade Log'!$R$5:$R$1004),"") | H12: =IF(A12<>"",SUMIF('Trade Log'!$B$5:$B$1004,A12,'Trade Log'!$T$5:$T$1004),"") | I12: =IF(A12<>"",IFERROR(SUMIF('Trade Log'!$B$5:$B$1004,A12,'Trade Log'!$R$5:$R$1004)/SUMIF('Trade Log'!$B$5:$B$1004,A12,'Trade Log'!$Q$5:$Q$1004)-1,""),"") | J12: =IF(A12<>"",SUMIF('Trade Log'!$B$5:$B$1004,A12,'Trade Log'!$V$5:$V$1004),"") | K12: =IF(A12<>"",IFERROR(SUMIF('Trade Log'!$B$5:$B$1004,A12,'Trade Log'!$V$5:$V$1004)/SUMIF('Trade Log'!$B$5:$B$1004,A12,'Trade Log'!$Q$5:$Q$1004),""),"") | L12: =IF(A12<>"",IFERROR(SUMIFS('Trade Log'!$L$5:$L$1004,'Trade Log'!$B$5:$B$1004,A12,'Trade Log'!$E$5:$E$1004,""),0),"") | M12: =IF(A12<>"",IFERROR(INDEX('Trade Log'!$AB$5:$AB$1004,MATCH(2,1/('Trade Log'!$B$5:$B$1004=A12),1)),""),"")
B13: =IF(A13<>"",IFERROR(INDEX('Trade Log'!$G$5:$G$1004,MATCH(A13,'Trade Log'!$B$5:$B$1004,0)),""),"") | C13: =IF(A13<>"",IFERROR(INDEX('Trade Log'!$I$5:$I$1004,MATCH(A13,'Trade Log'!$B$5:$B$1004,0)),""),"") | D13: =IF(A13<>"",COUNTIF('Trade Log'!$B$5:$B$1004,A13),"") | E13: =IF(A13<>"",SUMIF('Trade Log'!$B$5:$B$1004,A13,'Trade Log'!$L$5:$L$1004),"") | F13: =IF(A13<>"",SUMIF('Trade Log'!$B$5:$B$1004,A13,'Trade Log'!$Q$5:$Q$1004),"") | G13: =IF(A13<>"",SUMIF('Trade Log'!$B$5:$B$1004,A13,'Trade Log'!$R$5:$R$1004),"") | H13: =IF(A13<>"",SUMIF('Trade Log'!$B$5:$B$1004,A13,'Trade Log'!$T$5:$T$1004),"") | I13: =IF(A13<>"",IFERROR(SUMIF('Trade Log'!$B$5:$B$1004,A13,'Trade Log'!$R$5:$R$1004)/SUMIF('Trade Log'!$B$5:$B$1004,A13,'Trade Log'!$Q$5:$Q$1004)-1,""),"") | J13: =IF(A13<>"",SUMIF('Trade Log'!$B$5:$B$1004,A13,'Trade Log'!$V$5:$V$1004),"") | K13: =IF(A13<>"",IFERROR(SUMIF('Trade Log'!$B$5:$B$1004,A13,'Trade Log'!$V$5:$V$1004)/SUMIF('Trade Log'!$B$5:$B$1004,A13,'Trade Log'!$Q$5:$Q$1004),""),"") | L13: =IF(A13<>"",IFERROR(SUMIFS('Trade Log'!$L$5:$L$1004,'Trade Log'!$B$5:$B$1004,A13,'Trade Log'!$E$5:$E$1004,""),0),"") | M13: =IF(A13<>"",IFERROR(INDEX('Trade Log'!$AB$5:$AB$1004,MATCH(2,1/('Trade Log'!$B$5:$B$1004=A13),1)),""),"")
B14: =IF(A14<>"",IFERROR(INDEX('Trade Log'!$G$5:$G$1004,MATCH(A14,'Trade Log'!$B$5:$B$1004,0)),""),"") | C14: =IF(A14<>"",IFERROR(INDEX('Trade Log'!$I$5:$I$1004,MATCH(A14,'Trade Log'!$B$5:$B$1004,0)),""),"") | D14: =IF(A14<>"",COUNTIF('Trade Log'!$B$5:$B$1004,A14),"") | E14: =IF(A14<>"",SUMIF('Trade Log'!$B$5:$B$1004,A14,'Trade Log'!$L$5:$L$1004),"") | F14: =IF(A14<>"",SUMIF('Trade Log'!$B$5:$B$1004,A14,'Trade Log'!$Q$5:$Q$1004),"") | G14: =IF(A14<>"",SUMIF('Trade Log'!$B$5:$B$1004,A14,'Trade Log'!$R$5:$R$1004),"") | H14: =IF(A14<>"",SUMIF('Trade Log'!$B$5:$B$1004,A14,'Trade Log'!$T$5:$T$1004),"") | I14: =IF(A14<>"",IFERROR(SUMIF('Trade Log'!$B$5:$B$1004,A14,'Trade Log'!$R$5:$R$1004)/SUMIF('Trade Log'!$B$5:$B$1004,A14,'Trade Log'!$Q$5:$Q$1004)-1,""),"") | J14: =IF(A14<>"",SUMIF('Trade Log'!$B$5:$B$1004,A14,'Trade Log'!$V$5:$V$1004),"") | K14: =IF(A14<>"",IFERROR(SUMIF('Trade Log'!$B$5:$B$1004,A14,'Trade Log'!$V$5:$V$1004)/SUMIF('Trade Log'!$B$5:$B$1004,A14,'Trade Log'!$Q$5:$Q$1004),""),"") | L14: =IF(A14<>"",IFERROR(SUMIFS('Trade Log'!$L$5:$L$1004,'Trade Log'!$B$5:$B$1004,A14,'Trade Log'!$E$5:$E$1004,""),0),"") | M14: =IF(A14<>"",IFERROR(INDEX('Trade Log'!$AB$5:$AB$1004,MATCH(2,1/('Trade Log'!$B$5:$B$1004=A14),1)),""),"")
B15: =IF(A15<>"",IFERROR(INDEX('Trade Log'!$G$5:$G$1004,MATCH(A15,'Trade Log'!$B$5:$B$1004,0)),""),"") | C15: =IF(A15<>"",IFERROR(INDEX('Trade Log'!$I$5:$I$1004,MATCH(A15,'Trade Log'!$B$5:$B$1004,0)),""),"") | D15: =IF(A15<>"",COUNTIF('Trade Log'!$B$5:$B$1004,A15),"") | E15: =IF(A15<>"",SUMIF('Trade Log'!$B$5:$B$1004,A15,'Trade Log'!$L$5:$L$1004),"") | F15: =IF(A15<>"",SUMIF('Trade Log'!$B$5:$B$1004,A15,'Trade Log'!$Q$5:$Q$1004),"") | G15: =IF(A15<>"",SUMIF('Trade Log'!$B$5:$B$1004,A15,'Trade Log'!$R$5:$R$1004),"") | H15: =IF(A15<>"",SUMIF('Trade Log'!$B$5:$B$1004,A15,'Trade Log'!$T$5:$T$1004),"") | I15: =IF(A15<>"",IFERROR(SUMIF('Trade Log'!$B$5:$B$1004,A15,'Trade Log'!$R$5:$R$1004)/SUMIF('Trade Log'!$B$5:$B$1004,A15,'Trade Log'!$Q$5:$Q$1004)-1,""),"") | J15: =IF(A15<>"",SUMIF('Trade Log'!$B$5:$B$1004,A15,'Trade Log'!$V$5:$V$1004),"") | K15: =IF(A15<>"",IFERROR(SUMIF('Trade Log'!$B$5:$B$1004,A15,'Trade Log'!$V$5:$V$1004)/SUMIF('Trade Log'!$B$5:$B$1004,A15,'Trade Log'!$Q$5:$Q$1004),""),"") | L15: =IF(A15<>"",IFERROR(SUMIFS('Trade Log'!$L$5:$L$1004,'Trade Log'!$B$5:$B$1004,A15,'Trade Log'!$E$5:$E$1004,""),0),"") | M15: =IF(A15<>"",IFERROR(INDEX('Trade Log'!$AB$5:$AB$1004,MATCH(2,1/('Trade Log'!$B$5:$B$1004=A15),1)),""),"")
B16: =IF(A16<>"",IFERROR(INDEX('Trade Log'!$G$5:$G$1004,MATCH(A16,'Trade Log'!$B$5:$B$1004,0)),""),"") | C16: =IF(A16<>"",IFERROR(INDEX('Trade Log'!$I$5:$I$1004,MATCH(A16,'Trade Log'!$B$5:$B$1004,0)),""),"") | D16: =IF(A16<>"",COUNTIF('Trade Log'!$B$5:$B$1004,A16),"") | E16: =IF(A16<>"",SUMIF('Trade Log'!$B$5:$B$1004,A16,'Trade Log'!$L$5:$L$1004),"") | F16: =IF(A16<>"",SUMIF('Trade Log'!$B$5:$B$1004,A16,'Trade Log'!$Q$5:$Q$1004),"") | G16: =IF(A16<>"",SUMIF('Trade Log'!$B$5:$B$1004,A16,'Trade Log'!$R$5:$R$1004),"") | H16: =IF(A16<>"",SUMIF('Trade Log'!$B$5:$B$1004,A16,'Trade Log'!$T$5:$T$1004),"") | I16: =IF(A16<>"",IFERROR(SUMIF('Trade Log'!$B$5:$B$1004,A16,'Trade Log'!$R$5:$R$1004)/SUMIF('Trade Log'!$B$5:$B$1004,A16,'Trade Log'!$Q$5:$Q$1004)-1,""),"") | J16: =IF(A16<>"",SUMIF('Trade Log'!$B$5:$B$1004,A16,'Trade Log'!$V$5:$V$1004),"") | K16: =IF(A16<>"",IFERROR(SUMIF('Trade Log'!$B$5:$B$1004,A16,'Trade Log'!$V$5:$V$1004)/SUMIF('Trade Log'!$B$5:$B$1004,A16,'Trade Log'!$Q$5:$Q$1004),""),"") | L16: =IF(A16<>"",IFERROR(SUMIFS('Trade Log'!$L$5:$L$1004,'Trade Log'!$B$5:$B$1004,A16,'Trade Log'!$E$5:$E$1004,""),0),"") | M16: =IF(A16<>"",IFERROR(INDEX('Trade Log'!$AB$5:$AB$1004,MATCH(2,1/('Trade Log'!$B$5:$B$1004=A16),1)),""),"")
B17: =IF(A17<>"",IFERROR(INDEX('Trade Log'!$G$5:$G$1004,MATCH(A17,'Trade Log'!$B$5:$B$1004,0)),""),"") | C17: =IF(A17<>"",IFERROR(INDEX('Trade Log'!$I$5:$I$1004,MATCH(A17,'Trade Log'!$B$5:$B$1004,0)),""),"") | D17: =IF(A17<>"",COUNTIF('Trade Log'!$B$5:$B$1004,A17),"") | E17: =IF(A17<>"",SUMIF('Trade Log'!$B$5:$B$1004,A17,'Trade Log'!$L$5:$L$1004),"") | F17: =IF(A17<>"",SUMIF('Trade Log'!$B$5:$B$1004,A17,'Trade Log'!$Q$5:$Q$1004),"") | G17: =IF(A17<>"",SUMIF('Trade Log'!$B$5:$B$1004,A17,'Trade Log'!$R$5:$R$1004),"") | H17: =IF(A17<>"",SUMIF('Trade Log'!$B$5:$B$1004,A17,'Trade Log'!$T$5:$T$1004),"") | I17: =IF(A17<>"",IFERROR(SUMIF('Trade Log'!$B$5:$B$1004,A17,'Trade Log'!$R$5:$R$1004)/SUMIF('Trade Log'!$B$5:$B$1004,A17,'Trade Log'!$Q$5:$Q$1004)-1,""),"") | J17: =IF(A17<>"",SUMIF('Trade Log'!$B$5:$B$1004,A17,'Trade Log'!$V$5:$V$1004),"") | K17: =IF(A17<>"",IFERROR(SUMIF('Trade Log'!$B$5:$B$1004,A17,'Trade Log'!$V$5:$V$1004)/SUMIF('Trade Log'!$B$5:$B$1004,A17,'Trade Log'!$Q$5:$Q$1004),""),"") | L17: =IF(A17<>"",IFERROR(SUMIFS('Trade Log'!$L$5:$L$1004,'Trade Log'!$B$5:$B$1004,A17,'Trade Log'!$E$5:$E$1004,""),0),"") | M17: =IF(A17<>"",IFERROR(INDEX('Trade Log'!$AB$5:$AB$1004,MATCH(2,1/('Trade Log'!$B$5:$B$1004=A17),1)),""),"")
... B204: =IF(A204<>"",IFERROR(INDEX('Trade Log'!$G$5:$G$1004,MATCH(A204,'Trade Log'!$B$5:$B$1004,0)),""),"") | C204: =IF(A204<>"",IFERROR(INDEX('Trade Log'!$I$5:$I$1004,MATCH(A204,'Trade Log'!$B$5:$B$1004,0)),""),"") | D204: =IF(A204<>"",COUNTIF('Trade Log'!$B$5:$B$1004,A204),"") | E204: =IF(A204<>"",SUMIF('Trade Log'!$B$5:$B$1004,A204,'Trade Log'!$L$5:$L$1004),"") | F204: =IF(A204<>"",SUMIF('Trade Log'!$B$5:$B$1004,A204,'Trade Log'!$Q$5:$Q$1004),"") | G204: =IF(A204<>"",SUMIF('Trade Log'!$B$5:$B$1004,A204,'Trade Log'!$R$5:$R$1004),"") | H204: =IF(A204<>"",SUMIF('Trade Log'!$B$5:$B$1004,A204,'Trade Log'!$T$5:$T$1004),"") | I204: =IF(A204<>"",IFERROR(SUMIF('Trade Log'!$B$5:$B$1004,A204,'Trade Log'!$R$5:$R$1004)/SUMIF('Trade Log'!$B$5:$B$1004,A204,'Trade Log'!$Q$5:$Q$1004)-1,""),"") | J204: =IF(A204<>"",SUMIF('Trade Log'!$B$5:$B$1004,A204,'Trade Log'!$V$5:$V$1004),"") | K204: =IF(A204<>"",IFERROR(SUMIF('Trade Log'!$B$5:$B$1004,A204,'Trade Log'!$V$5:$V$1004)/SUMIF('Trade Log'!$B$5:$B$1004,A204,'Trade Log'!$Q$5:$Q$1004),""),"") | L204: =IF(A204<>"",IFERROR(SUMIFS('Trade Log'!$L$5:$L$1004,'Trade Log'!$B$5:$B$1004,A204,'Trade Log'!$E$5:$E$1004,""),0),"") | M204: =IF(A204<>"",IFERROR(INDEX('Trade Log'!$AB$5:$AB$1004,MATCH(2,1/('Trade Log'!$B$5:$B$1004=A204),1)),""),"")

Sheet Dashboard
A1: 📊 TRADE DASHBOARD
A2: Auto-updates from Trade Log · Individual fill stats · See Position Summary for rolled-up position P&L
A4: TOTAL FILLS | B4: WIN RATE | C4: TOTAL P&L | D4: BEST TRADE ($) | E4: WORST TRADE ($) | F4: AVG P&L / FILL | G4: AVG P&L % | H4: MAX P&L % | I4: TOTAL MAX P&L | J4: $ LEFT ON TABLE
A5: =COUNTA('Trade Log'!G5:G1004) -> 0 | B5: =IFERROR(COUNTIF('Trade Log'!T5:T1004,">0")/COUNTA('Trade Log'!T5:T1004),"—") -> 0 | C5: =IFERROR(SUM('Trade Log'!T5:T1004),"—") -> 0 | D5: =IFERROR(MAX('Trade Log'!T5:T1004),"—") -> 0 | E5: =IFERROR(MIN('Trade Log'!T5:T1004),"—") -> 0 | F5: =IFERROR(AVERAGE('Trade Log'!T5:T1004),"—") -> — | G5: =IFERROR(AVERAGE('Trade Log'!U5:U1004),"—") -> — | H5: =IFERROR(MAX('Trade Log'!U5:U1004),"—") -> 0 | I5: =IFERROR(SUM('Trade Log'!V5:V1004),"—") -> 0 | J5: =IFERROR(SUM('Trade Log'!V5:V1004)-SUM('Trade Log'!T5:T1004),"—") -> 0
A7: AVG ACTUAL R:R | B7: TOTAL FEES | D7: AVG DAYS HELD | E7: TOTAL POSITIONS | F7: BEST TICKER | G7: BEST TICKER P&L | H7: MOST TRADED | I7: AVG MAX P&L % | J7: MAX POSSIBLE %
A8: =IFERROR(CONCATENATE("1 : ",TEXT(AVERAGEIF('Trade Log'!O5:O1004,"<>",'Trade Log'!U5:U1004),"0.00")),"—") -> — | B8: =IFERROR(SUM('Trade Log'!N5:N1004),"—") -> 0 | D8: =IFERROR(AVERAGEIF('Trade Log'!AA5:AA1004,">0"),"—") -> — | E8: =IFERROR(COUNTA(unique(filter('Trade Log'!B5:B1004,'Trade Log'!B5:B1004<>""))),"—") -> 1 | F8: =IFERROR(INDEX($A$24:$A$123,MATCH(MAX(IFERROR($C$24:$C$123*1,0)),$C$24:$C$123,0)),"—") -> — | G8: =IFERROR(IF(F8="—","—",SUMIF('Trade Log'!$G$5:$G$1004,F8,'Trade Log'!$T$5:$T$1004)),"—") -> — | H8: =IFERROR(INDEX('Trade Log'!G5:G1004,MATCH(MAX(COUNTIF('Trade Log'!G5:G1004,unique(filter('Trade Log'!G5:G1004,'Trade Log'!G5:G1004<>"")))),COUNTIF('Trade Log'!G5:G1004,unique(filter('Trade Log'!G5:G1004,'Trade Log'!G5:G1004<>""))),0)),"—") -> — | I8: =IFERROR(AVERAGE('Trade Log'!W5:W1004),"—") -> — | J8: =IFERROR(MAX('Trade Log'!W5:W1004),"—") -> 0
A10: Strategy | B10: # Fills | C10: Total P&L | D10: Win Rate | E10: Avg P&L | F10: Avg P&L % | G10: Max P&L % | H10: Best Trade | I10: Avg Max P&L % | J10: Left on Table
A11: Long Call | B11: =COUNTIF('Trade Log'!I5:I1004,"Long Call") -> 0 | C11: =IFERROR(SUMIF('Trade Log'!I5:I1004,"Long Call",'Trade Log'!T5:T1004),"—") -> 0 | D11: =IFERROR(COUNTIFS('Trade Log'!I5:I1004,"Long Call",'Trade Log'!T5:T1004,">0")/COUNTIF('Trade Log'!I5:I1004,"Long Call"),"—") -> — | E11: =IFERROR(AVERAGEIF('Trade Log'!I5:I1004,"Long Call",'Trade Log'!T5:T1004),"—") -> — | F11: =IFERROR(AVERAGEIF('Trade Log'!I5:I1004,"Long Call",'Trade Log'!U5:U1004),"—") -> — | G11: =IFERROR(maxifs('Trade Log'!U5:U1004,'Trade Log'!I5:I1004,"Long Call"),"—") -> — | H11: =IFERROR(maxifs('Trade Log'!T5:T1004,'Trade Log'!I5:I1004,"Long Call"),"—") -> — | I11: =IFERROR(AVERAGEIF('Trade Log'!I5:I1004,"Long Call",'Trade Log'!W5:W1004),"—") -> — | J11: =IFERROR(SUMIF('Trade Log'!I5:I1004,"Long Call",'Trade Log'!V5:V1004)-SUMIF('Trade Log'!I5:I1004,"Long Call",'Trade Log'!T5:T1004),"—") -> 0
A12: Long Put | B12: =COUNTIF('Trade Log'!I5:I1004,"Long Put") -> 0 | C12: =IFERROR(SUMIF('Trade Log'!I5:I1004,"Long Put",'Trade Log'!T5:T1004),"—") -> 0 | D12: =IFERROR(COUNTIFS('Trade Log'!I5:I1004,"Long Put",'Trade Log'!T5:T1004,">0")/COUNTIF('Trade Log'!I5:I1004,"Long Put"),"—") -> — | E12: =IFERROR(AVERAGEIF('Trade Log'!I5:I1004,"Long Put",'Trade Log'!T5:T1004),"—") -> — | F12: =IFERROR(AVERAGEIF('Trade Log'!I5:I1004,"Long Put",'Trade Log'!U5:U1004),"—") -> — | G12: =IFERROR(maxifs('Trade Log'!U5:U1004,'Trade Log'!I5:I1004,"Long Put"),"—") -> — | H12: =IFERROR(maxifs('Trade Log'!T5:T1004,'Trade Log'!I5:I1004,"Long Put"),"—") -> — | I12: =IFERROR(AVERAGEIF('Trade Log'!I5:I1004,"Long Put",'Trade Log'!W5:W1004),"—") -> — | J12: =IFERROR(SUMIF('Trade Log'!I5:I1004,"Long Put",'Trade Log'!V5:V1004)-SUMIF('Trade Log'!I5:I1004,"Long Put",'Trade Log'!T5:T1004),"—") -> 0
A13: Covered Call | B13: =COUNTIF('Trade Log'!I5:I1004,"Covered Call") -> 0 | C13: =IFERROR(SUMIF('Trade Log'!I5:I1004,"Covered Call",'Trade Log'!T5:T1004),"—") -> 0 | D13: =IFERROR(COUNTIFS('Trade Log'!I5:I1004,"Covered Call",'Trade Log'!T5:T1004,">0")/COUNTIF('Trade Log'!I5:I1004,"Covered Call"),"—") -> — | E13: =IFERROR(AVERAGEIF('Trade Log'!I5:I1004,"Covered Call",'Trade Log'!T5:T1004),"—") -> — | F13: =IFERROR(AVERAGEIF('Trade Log'!I5:I1004,"Covered Call",'Trade Log'!U5:U1004),"—") -> — | G13: =IFERROR(maxifs('Trade Log'!U5:U1004,'Trade Log'!I5:I1004,"Covered Call"),"—") -> — | H13: =IFERROR(maxifs('Trade Log'!T5:T1004,'Trade Log'!I5:I1004,"Covered Call"),"—") -> — | I13: =IFERROR(AVERAGEIF('Trade Log'!I5:I1004,"Covered Call",'Trade Log'!W5:W1004),"—") -> — | J13: =IFERROR(SUMIF('Trade Log'!I5:I1004,"Covered Call",'Trade Log'!V5:V1004)-SUMIF('Trade Log'!I5:I1004,"Covered Call",'Trade Log'!T5:T1004),"—") -> 0
A14: Cash-Secured Put | B14: =COUNTIF('Trade Log'!I5:I1004,"Cash-Secured Put") -> 0 | C14: =IFERROR(SUMIF('Trade Log'!I5:I1004,"Cash-Secured Put",'Trade Log'!T5:T1004),"—") -> 0 | D14: =IFERROR(COUNTIFS('Trade Log'!I5:I1004,"Cash-Secured Put",'Trade Log'!T5:T1004,">0")/COUNTIF('Trade Log'!I5:I1004,"Cash-Secured Put"),"—") -> — | E14: =IFERROR(AVERAGEIF('Trade Log'!I5:I1004,"Cash-Secured Put",'Trade Log'!T5:T1004),"—") -> — | F14: =IFERROR(AVERAGEIF('Trade Log'!I5:I1004,"Cash-Secured Put",'Trade Log'!U5:U1004),"—") -> — | G14: =IFERROR(maxifs('Trade Log'!U5:U1004,'Trade Log'!I5:I1004,"Cash-Secured Put"),"—") -> — | H14: =IFERROR(maxifs('Trade Log'!T5:T1004,'Trade Log'!I5:I1004,"Cash-Secured Put"),"—") -> — | I14: =IFERROR(AVERAGEIF('Trade Log'!I5:I1004,"Cash-Secured Put",'Trade Log'!W5:W1004),"—") -> — | J14: =IFERROR(SUMIF('Trade Log'!I5:I1004,"Cash-Secured Put",'Trade Log'!V5:V1004)-SUMIF('Trade Log'!I5:I1004,"Cash-Secured Put",'Trade Log'!T5:T1004),"—") -> 0
A15: Bull Call Spread | B15: =COUNTIF('Trade Log'!I5:I1004,"Bull Call Spread") -> 0 | C15: =IFERROR(SUMIF('Trade Log'!I5:I1004,"Bull Call Spread",'Trade Log'!T5:T1004),"—") -> 0 | D15: =IFERROR(COUNTIFS('Trade Log'!I5:I1004,"Bull Call Spread",'Trade Log'!T5:T1004,">0")/COUNTIF('Trade Log'!I5:I1004,"Bull Call Spread"),"—") -> — | E15: =IFERROR(AVERAGEIF('Trade Log'!I5:I1004,"Bull Call Spread",'Trade Log'!T5:T1004),"—") -> — | F15: =IFERROR(AVERAGEIF('Trade Log'!I5:I1004,"Bull Call Spread",'Trade Log'!U5:U1004),"—") -> — | G15: =IFERROR(maxifs('Trade Log'!U5:U1004,'Trade Log'!I5:I1004,"Bull Call Spread"),"—") -> — | H15: =IFERROR(maxifs('Trade Log'!T5:T1004,'Trade Log'!I5:I1004,"Bull Call Spread"),"—") -> — | I15: =IFERROR(AVERAGEIF('Trade Log'!I5:I1004,"Bull Call Spread",'Trade Log'!W5:W1004),"—") -> — | J15: =IFERROR(SUMIF('Trade Log'!I5:I1004,"Bull Call Spread",'Trade Log'!V5:V1004)-SUMIF('Trade Log'!I5:I1004,"Bull Call Spread",'Trade Log'!T5:T1004),"—") -> 0
A16: Bear Put Spread | B16: =COUNTIF('Trade Log'!I5:I1004,"Bear Put Spread") -> 0 | C16: =IFERROR(SUMIF('Trade Log'!I5:I1004,"Bear Put Spread",'Trade Log'!T5:T1004),"—") -> 0 | D16: =IFERROR(COUNTIFS('Trade Log'!I5:I1004,"Bear Put Spread",'Trade Log'!T5:T1004,">0")/COUNTIF('Trade Log'!I5:I1004,"Bear Put Spread"),"—") -> — | E16: =IFERROR(AVERAGEIF('Trade Log'!I5:I1004,"Bear Put Spread",'Trade Log'!T5:T1004),"—") -> — | F16: =IFERROR(AVERAGEIF('Trade Log'!I5:I1004,"Bear Put Spread",'Trade Log'!U5:U1004),"—") -> — | G16: =IFERROR(maxifs('Trade Log'!U5:U1004,'Trade Log'!I5:I1004,"Bear Put Spread"),"—") -> — | H16: =IFERROR(maxifs('Trade Log'!T5:T1004,'Trade Log'!I5:I1004,"Bear Put Spread"),"—") -> — | I16: =IFERROR(AVERAGEIF('Trade Log'!I5:I1004,"Bear Put Spread",'Trade Log'!W5:W1004),"—") -> — | J16: =IFERROR(SUMIF('Trade Log'!I5:I1004,"Bear Put Spread",'Trade Log'!V5:V1004)-SUMIF('Trade Log'!I5:I1004,"Bear Put Spread",'Trade Log'!T5:T1004),"—") -> 0
A17: Iron Condor | B17: =COUNTIF('Trade Log'!I5:I1004,"Iron Condor") -> 0 | C17: =IFERROR(SUMIF('Trade Log'!I5:I1004,"Iron Condor",'Trade Log'!T5:T1004),"—") -> 0 | D17: =IFERROR(COUNTIFS('Trade Log'!I5:I1004,"Iron Condor",'Trade Log'!T5:T1004,">0")/COUNTIF('Trade Log'!I5:I1004,"Iron Condor"),"—") -> — | E17: =IFERROR(AVERAGEIF('Trade Log'!I5:I1004,"Iron Condor",'Trade Log'!T5:T1004),"—") -> — | F17: =IFERROR(AVERAGEIF('Trade Log'!I5:I1004,"Iron Condor",'Trade Log'!U5:U1004),"—") -> — | G17: =IFERROR(maxifs('Trade Log'!U5:U1004,'Trade Log'!I5:I1004,"Iron Condor"),"—") -> — | H17: =IFERROR(maxifs('Trade Log'!T5:T1004,'Trade Log'!I5:I1004,"Iron Condor"),"—") -> — | I17: =IFERROR(AVERAGEIF('Trade Log'!I5:I1004,"Iron Condor",'Trade Log'!W5:W1004),"—") -> — | J17: =IFERROR(SUMIF('Trade Log'!I5:I1004,"Iron Condor",'Trade Log'!V5:V1004)-SUMIF('Trade Log'!I5:I1004,"Iron Condor",'Trade Log'!T5:T1004),"—") -> 0
A18: Straddle | B18: =COUNTIF('Trade Log'!I5:I1004,"Straddle") -> 0 | C18: =IFERROR(SUMIF('Trade Log'!I5:I1004,"Straddle",'Trade Log'!T5:T1004),"—") -> 0 | D18: =IFERROR(COUNTIFS('Trade Log'!I5:I1004,"Straddle",'Trade Log'!T5:T1004,">0")/COUNTIF('Trade Log'!I5:I1004,"Straddle"),"—") -> — | E18: =IFERROR(AVERAGEIF('Trade Log'!I5:I1004,"Straddle",'Trade Log'!T5:T1004),"—") -> — | F18: =IFERROR(AVERAGEIF('Trade Log'!I5:I1004,"Straddle",'Trade Log'!U5:U1004),"—") -> — | G18: =IFERROR(maxifs('Trade Log'!U5:U1004,'Trade Log'!I5:I1004,"Straddle"),"—") -> — | H18: =IFERROR(maxifs('Trade Log'!T5:T1004,'Trade Log'!I5:I1004,"Straddle"),"—") -> — | I18: =IFERROR(AVERAGEIF('Trade Log'!I5:I1004,"Straddle",'Trade Log'!W5:W1004),"—") -> — | J18: =IFERROR(SUMIF('Trade Log'!I5:I1004,"Straddle",'Trade Log'!V5:V1004)-SUMIF('Trade Log'!I5:I1004,"Straddle",'Trade Log'!T5:T1004),"—") -> 0
A19: Other | B19: =COUNTIF('Trade Log'!I5:I1004,"Other") -> 0 | C19: =IFERROR(SUMIF('Trade Log'!I5:I1004,"Other",'Trade Log'!T5:T1004),"—") -> 0 | D19: =IFERROR(COUNTIFS('Trade Log'!I5:I1004,"Other",'Trade Log'!T5:T1004,">0")/COUNTIF('Trade Log'!I5:I1004,"Other"),"—") -> — | E19: =IFERROR(AVERAGEIF('Trade Log'!I5:I1004,"Other",'Trade Log'!T5:T1004),"—") -> — | F19: =IFERROR(AVERAGEIF('Trade Log'!I5:I1004,"Other",'Trade Log'!U5:U1004),"—") -> — | G19: =IFERROR(maxifs('Trade Log'!U5:U1004,'Trade Log'!I5:I1004,"Other"),"—") -> — | H19: =IFERROR(maxifs('Trade Log'!T5:T1004,'Trade Log'!I5:I1004,"Other"),"—") -> — | I19: =IFERROR(AVERAGEIF('Trade Log'!I5:I1004,"Other",'Trade Log'!W5:W1004),"—") -> — | J19: =IFERROR(SUMIF('Trade Log'!I5:I1004,"Other",'Trade Log'!V5:V1004)-SUMIF('Trade Log'!I5:I1004,"Other",'Trade Log'!T5:T1004),"—") -> 0
A22: 📈 TICKER PERFORMANCE
A23: Ticker | B23: # Fills | C23: Total P&L | D23: Win Rate | E23: Avg P&L | F23: Avg P&L % | G23: Best Trade ($) | H23: Worst Trade ($) | I23: Avg Max P&L % | J23: Max P&L %
A24: =IFERROR(unique(filter('Trade Log'!G5:G1004,'Trade Log'!G5:G1004<>"")),"") | B24: =IF(A24<>"",COUNTIF('Trade Log'!G5:G1004,A24),"") | C24: =IF(A24<>"",IFERROR(SUMIF('Trade Log'!G5:G1004,A24,'Trade Log'!T5:T1004),"—"),"") | D24: =IF(A24<>"",IFERROR(COUNTIFS('Trade Log'!G5:G1004,A24,'Trade Log'!T5:T1004,">0")/COUNTIF('Trade Log'!G5:G1004,A24),"—"),"") | E24: =IF(A24<>"",IFERROR(AVERAGEIF('Trade Log'!G5:G1004,A24,'Trade Log'!T5:T1004),"—"),"") | F24: =IF(A24<>"",IFERROR(AVERAGEIF('Trade Log'!G5:G1004,A24,'Trade Log'!U5:U1004),"—"),"") | G24: =IF(A24<>"",IFERROR(maxifs('Trade Log'!T5:T1004,'Trade Log'!G5:G1004,A24),"—"),"") | H24: =IF(A24<>"",IFERROR(minifs('Trade Log'!T5:T1004,'Trade Log'!G5:G1004,A24),"—"),"") | I24: =IF(A24<>"",IFERROR(AVERAGEIF('Trade Log'!G5:G1004,A24,'Trade Log'!W5:W1004),"—"),"") | J24: =IF(A24<>"",IFERROR(maxifs('Trade Log'!U5:U1004,'Trade Log'!G5:G1004,A24),"—"),"")
B25: =IF(A25<>"",COUNTIF('Trade Log'!G5:G1004,A25),"") | C25: =IF(A25<>"",IFERROR(SUMIF('Trade Log'!G5:G1004,A25,'Trade Log'!T5:T1004),"—"),"") | D25: =IF(A25<>"",IFERROR(COUNTIFS('Trade Log'!G5:G1004,A25,'Trade Log'!T5:T1004,">0")/COUNTIF('Trade Log'!G5:G1004,A25),"—"),"") | E25: =IF(A25<>"",IFERROR(AVERAGEIF('Trade Log'!G5:G1004,A25,'Trade Log'!T5:T1004),"—"),"") | F25: =IF(A25<>"",IFERROR(AVERAGEIF('Trade Log'!G5:G1004,A25,'Trade Log'!U5:U1004),"—"),"") | G25: =IF(A25<>"",IFERROR(maxifs('Trade Log'!T5:T1004,'Trade Log'!G5:G1004,A25),"—"),"") | H25: =IF(A25<>"",IFERROR(minifs('Trade Log'!T5:T1004,'Trade Log'!G5:G1004,A25),"—"),"") | I25: =IF(A25<>"",IFERROR(AVERAGEIF('Trade Log'!G5:G1004,A25,'Trade Log'!W5:W1004),"—"),"") | J25: =IF(A25<>"",IFERROR(maxifs('Trade Log'!U5:U1004,'Trade Log'!G5:G1004,A25),"—"),"")
B26: =IF(A26<>"",COUNTIF('Trade Log'!G5:G1004,A26),"") | C26: =IF(A26<>"",IFERROR(SUMIF('Trade Log'!G5:G1004,A26,'Trade Log'!T5:T1004),"—"),"") | D26: =IF(A26<>"",IFERROR(COUNTIFS('Trade Log'!G5:G1004,A26,'Trade Log'!T5:T1004,">0")/COUNTIF('Trade Log'!G5:G1004,A26),"—"),"") | E26: =IF(A26<>"",IFERROR(AVERAGEIF('Trade Log'!G5:G1004,A26,'Trade Log'!T5:T1004),"—"),"") | F26: =IF(A26<>"",IFERROR(AVERAGEIF('Trade Log'!G5:G1004,A26,'Trade Log'!U5:U1004),"—"),"") | G26: =IF(A26<>"",IFERROR(maxifs('Trade Log'!T5:T1004,'Trade Log'!G5:G1004,A26),"—"),"") | H26: =IF(A26<>"",IFERROR(minifs('Trade Log'!T5:T1004,'Trade Log'!G5:G1004,A26),"—"),"") | I26: =IF(A26<>"",IFERROR(AVERAGEIF('Trade Log'!G5:G1004,A26,'Trade Log'!W5:W1004),"—"),"") | J26: =IF(A26<>"",IFERROR(maxifs('Trade Log'!U5:U1004,'Trade Log'!G5:G1004,A26),"—"),"")
B27: =IF(A27<>"",COUNTIF('Trade Log'!G5:G1004,A27),"") | C27: =IF(A27<>"",IFERROR(SUMIF('Trade Log'!G5:G1004,A27,'Trade Log'!T5:T1004),"—"),"") | D27: =IF(A27<>"",IFERROR(COUNTIFS('Trade Log'!G5:G1004,A27,'Trade Log'!T5:T1004,">0")/COUNTIF('Trade Log'!G5:G1004,A27),"—"),"") | E27: =IF(A27<>"",IFERROR(AVERAGEIF('Trade Log'!G5:G1004,A27,'Trade Log'!T5:T1004),"—"),"") | F27: =IF(A27<>"",IFERROR(AVERAGEIF('Trade Log'!G5:G1004,A27,'Trade Log'!U5:U1004),"—"),"") | G27: =IF(A27<>"",IFERROR(maxifs('Trade Log'!T5:T1004,'Trade Log'!G5:G1004,A27),"—"),"") | H27: =IF(A27<>"",IFERROR(minifs('Trade Log'!T5:T1004,'Trade Log'!G5:G1004,A27),"—"),"") | I27: =IF(A27<>"",IFERROR(AVERAGEIF('Trade Log'!G5:G1004,A27,'Trade Log'!W5:W1004),"—"),"") | J27: =IF(A27<>"",IFERROR(maxifs('Trade Log'!U5:U1004,'Trade Log'!G5:G1004,A27),"—"),"")
B28: =IF(A28<>"",COUNTIF('Trade Log'!G5:G1004,A28),"") | C28: =IF(A28<>"",IFERROR(SUMIF('Trade Log'!G5:G1004,A28,'Trade Log'!T5:T1004),"—"),"") | D28: =IF(A28<>"",IFERROR(COUNTIFS('Trade Log'!G5:G1004,A28,'Trade Log'!T5:T1004,">0")/COUNTIF('Trade Log'!G5:G1004,A28),"—"),"") | E28: =IF(A28<>"",IFERROR(AVERAGEIF('Trade Log'!G5:G1004,A28,'Trade Log'!T5:T1004),"—"),"") | F28: =IF(A28<>"",IFERROR(AVERAGEIF('Trade Log'!G5:G1004,A28,'Trade Log'!U5:U1004),"—"),"") | G28: =IF(A28<>"",IFERROR(maxifs('Trade Log'!T5:T1004,'Trade Log'!G5:G1004,A28),"—"),"") | H28: =IF(A28<>"",IFERROR(minifs('Trade Log'!T5:T1004,'Trade Log'!G5:G1004,A28),"—"),"") | I28: =IF(A28<>"",IFERROR(AVERAGEIF('Trade Log'!G5:G1004,A28,'Trade Log'!W5:W1004),"—"),"") | J28: =IF(A28<>"",IFERROR(maxifs('Trade Log'!U5:U1004,'Trade Log'!G5:G1004,A28),"—"),"")
B29: =IF(A29<>"",COUNTIF('Trade Log'!G5:G1004,A29),"") | C29: =IF(A29<>"",IFERROR(SUMIF('Trade Log'!G5:G1004,A29,'Trade Log'!T5:T1004),"—"),"") | D29: =IF(A29<>"",IFERROR(COUNTIFS('Trade Log'!G5:G1004,A29,'Trade Log'!T5:T1004,">0")/COUNTIF('Trade Log'!G5:G1004,A29),"—"),"") | E29: =IF(A29<>"",IFERROR(AVERAGEIF('Trade Log'!G5:G1004,A29,'Trade Log'!T5:T1004),"—"),"") | F29: =IF(A29<>"",IFERROR(AVERAGEIF('Trade Log'!G5:G1004,A29,'Trade Log'!U5:U1004),"—"),"") | G29: =IF(A29<>"",IFERROR(maxifs('Trade Log'!T5:T1004,'Trade Log'!G5:G1004,A29),"—"),"") | H29: =IF(A29<>"",IFERROR(minifs('Trade Log'!T5:T1004,'Trade Log'!G5:G1004,A29),"—"),"") | I29: =IF(A29<>"",IFERROR(AVERAGEIF('Trade Log'!G5:G1004,A29,'Trade Log'!W5:W1004),"—"),"") | J29: =IF(A29<>"",IFERROR(maxifs('Trade Log'!U5:U1004,'Trade Log'!G5:G1004,A29),"—"),"")
B30: =IF(A30<>"",COUNTIF('Trade Log'!G5:G1004,A30),"") | C30: =IF(A30<>"",IFERROR(SUMIF('Trade Log'!G5:G1004,A30,'Trade Log'!T5:T1004),"—"),"") | D30: =IF(A30<>"",IFERROR(COUNTIFS('Trade Log'!G5:G1004,A30,'Trade Log'!T5:T1004,">0")/COUNTIF('Trade Log'!G5:G1004,A30),"—"),"") | E30: =IF(A30<>"",IFERROR(AVERAGEIF('Trade Log'!G5:G1004,A30,'Trade Log'!T5:T1004),"—"),"") | F30: =IF(A30<>"",IFERROR(AVERAGEIF('Trade Log'!G5:G1004,A30,'Trade Log'!U5:U1004),"—"),"") | G30: =IF(A30<>"",IFERROR(maxifs('Trade Log'!T5:T1004,'Trade Log'!G5:G1004,A30),"—"),"") | H30: =IF(A30<>"",IFERROR(minifs('Trade Log'!T5:T1004,'Trade Log'!G5:G1004,A30),"—"),"") | I30: =IF(A30<>"",IFERROR(AVERAGEIF('Trade Log'!G5:G1004,A30,'Trade Log'!W5:W1004),"—"),"") | J30: =IF(A30<>"",IFERROR(maxifs('Trade Log'!U5:U1004,'Trade Log'!G5:G1004,A30),"—"),"")
B31: =IF(A31<>"",COUNTIF('Trade Log'!G5:G1004,A31),"") | C31: =IF(A31<>"",IFERROR(SUMIF('Trade Log'!G5:G1004,A31,'Trade Log'!T5:T1004),"—"),"") | D31: =IF(A31<>"",IFERROR(COUNTIFS('Trade Log'!G5:G1004,A31,'Trade Log'!T5:T1004,">0")/COUNTIF('Trade Log'!G5:G1004,A31),"—"),"") | E31: =IF(A31<>"",IFERROR(AVERAGEIF('Trade Log'!G5:G1004,A31,'Trade Log'!T5:T1004),"—"),"") | F31: =IF(A31<>"",IFERROR(AVERAGEIF('Trade Log'!G5:G1004,A31,'Trade Log'!U5:U1004),"—"),"") | G31: =IF(A31<>"",IFERROR(maxifs('Trade Log'!T5:T1004,'Trade Log'!G5:G1004,A31),"—"),"") | H31: =IF(A31<>"",IFERROR(minifs('Trade Log'!T5:T1004,'Trade Log'!G5:G1004,A31),"—"),"") | I31: =IF(A31<>"",IFERROR(AVERAGEIF('Trade Log'!G5:G1004,A31,'Trade Log'!W5:W1004),"—"),"") | J31: =IF(A31<>"",IFERROR(maxifs('Trade Log'!U5:U1004,'Trade Log'!G5:G1004,A31),"—"),"")
B32: =IF(A32<>"",COUNTIF('Trade Log'!G5:G1004,A32),"") | C32: =IF(A32<>"",IFERROR(SUMIF('Trade Log'!G5:G1004,A32,'Trade Log'!T5:T1004),"—"),"") | D32: =IF(A32<>"",IFERROR(COUNTIFS('Trade Log'!G5:G1004,A32,'Trade Log'!T5:T1004,">0")/COUNTIF('Trade Log'!G5:G1004,A32),"—"),"") | E32: =IF(A32<>"",IFERROR(AVERAGEIF('Trade Log'!G5:G1004,A32,'Trade Log'!T5:T1004),"—"),"") | F32: =IF(A32<>"",IFERROR(AVERAGEIF('Trade Log'!G5:G1004,A32,'Trade Log'!U5:U1004),"—"),"") | G32: =IF(A32<>"",IFERROR(maxifs('Trade Log'!T5:T1004,'Trade Log'!G5:G1004,A32),"—"),"") | H32: =IF(A32<>"",IFERROR(minifs('Trade Log'!T5:T1004,'Trade Log'!G5:G1004,A32),"—"),"") | I32: =IF(A32<>"",IFERROR(AVERAGEIF('Trade Log'!G5:G1004,A32,'Trade Log'!W5:W1004),"—"),"") | J32: =IF(A32<>"",IFERROR(maxifs('Trade Log'!U5:U1004,'Trade Log'!G5:G1004,A32),"—"),"")
B33: =IF(A33<>"",COUNTIF('Trade Log'!G5:G1004,A33),"") | C33: =IF(A33<>"",IFERROR(SUMIF('Trade Log'!G5:G1004,A33,'Trade Log'!T5:T1004),"—"),"") | D33: =IF(A33<>"",IFERROR(COUNTIFS('Trade Log'!G5:G1004,A33,'Trade Log'!T5:T1004,">0")/COUNTIF('Trade Log'!G5:G1004,A33),"—"),"") | E33: =IF(A33<>"",IFERROR(AVERAGEIF('Trade Log'!G5:G1004,A33,'Trade Log'!T5:T1004),"—"),"") | F33: =IF(A33<>"",IFERROR(AVERAGEIF('Trade Log'!G5:G1004,A33,'Trade Log'!U5:U1004),"—"),"") | G33: =IF(A33<>"",IFERROR(maxifs('Trade Log'!T5:T1004,'Trade Log'!G5:G1004,A33),"—"),"") | H33: =IF(A33<>"",IFERROR(minifs('Trade Log'!T5:T1004,'Trade Log'!G5:G1004,A33),"—"),"") | I33: =IF(A33<>"",IFERROR(AVERAGEIF('Trade Log'!G5:G1004,A33,'Trade Log'!W5:W1004),"—"),"") | J33: =IF(A33<>"",IFERROR(maxifs('Trade Log'!U5:U1004,'Trade Log'!G5:G1004,A33),"—"),"")
B34: =IF(A34<>"",COUNTIF('Trade Log'!G5:G1004,A34),"") | C34: =IF(A34<>"",IFERROR(SUMIF('Trade Log'!G5:G1004,A34,'Trade Log'!T5:T1004),"—"),"") | D34: =IF(A34<>"",IFERROR(COUNTIFS('Trade Log'!G5:G1004,A34,'Trade Log'!T5:T1004,">0")/COUNTIF('Trade Log'!G5:G1004,A34),"—"),"") | E34: =IF(A34<>"",IFERROR(AVERAGEIF('Trade Log'!G5:G1004,A34,'Trade Log'!T5:T1004),"—"),"") | F34: =IF(A34<>"",IFERROR(AVERAGEIF('Trade Log'!G5:G1004,A34,'Trade Log'!U5:U1004),"—"),"") | G34: =IF(A34<>"",IFERROR(maxifs('Trade Log'!T5:T1004,'Trade Log'!G5:G1004,A34),"—"),"") | H34: =IF(A34<>"",IFERROR(minifs('Trade Log'!T5:T1004,'Trade Log'!G5:G1004,A34),"—"),"") | I34: =IF(A34<>"",IFERROR(AVERAGEIF('Trade Log'!G5:G1004,A34,'Trade Log'!W5:W1004),"—"),"") | J34: =IF(A34<>"",IFERROR(maxifs('Trade Log'!U5:U1004,'Trade Log'!G5:G1004,A34),"—"),"")
B35: =IF(A35<>"",COUNTIF('Trade Log'!G5:G1004,A35),"") | C35: =IF(A35<>"",IFERROR(SUMIF('Trade Log'!G5:G1004,A35,'Trade Log'!T5:T1004),"—"),"") | D35: =IF(A35<>"",IFERROR(COUNTIFS('Trade Log'!G5:G1004,A35,'Trade Log'!T5:T1004,">0")/COUNTIF('Trade Log'!G5:G1004,A35),"—"),"") | E35: =IF(A35<>"",IFERROR(AVERAGEIF('Trade Log'!G5:G1004,A35,'Trade Log'!T5:T1004),"—"),"") | F35: =IF(A35<>"",IFERROR(AVERAGEIF('Trade Log'!G5:G1004,A35,'Trade Log'!U5:U1004),"—"),"") | G35: =IF(A35<>"",IFERROR(maxifs('Trade Log'!T5:T1004,'Trade Log'!G5:G1004,A35),"—"),"") | H35: =IF(A35<>"",IFERROR(minifs('Trade Log'!T5:T1004,'Trade Log'!G5:G1004,A35),"—"),"") | I35: =IF(A35<>"",IFERROR(AVERAGEIF('Trade Log'!G5:G1004,A35,'Trade Log'!W5:W1004),"—"),"") | J35: =IF(A35<>"",IFERROR(maxifs('Trade Log'!U5:U1004,'Trade Log'!G5:G1004,A35),"—"),"")
B36: =IF(A36<>"",COUNTIF('Trade Log'!G5:G1004,A36),"") | C36: =IF(A36<>"",IFERROR(SUMIF('Trade Log'!G5:G1004,A36,'Trade Log'!T5:T1004),"—"),"") | D36: =IF(A36<>"",IFERROR(COUNTIFS('Trade Log'!G5:G1004,A36,'Trade Log'!T5:T1004,">0")/COUNTIF('Trade Log'!G5:G1004,A36),"—"),"") | E36: =IF(A36<>"",IFERROR(AVERAGEIF('Trade Log'!G5:G1004,A36,'Trade Log'!T5:T1004),"—"),"") | F36: =IF(A36<>"",IFERROR(AVERAGEIF('Trade Log'!G5:G1004,A36,'Trade Log'!U5:U1004),"—"),"") | G36: =IF(A36<>"",IFERROR(maxifs('Trade Log'!T5:T1004,'Trade Log'!G5:G1004,A36),"—"),"") | H36: =IF(A36<>"",IFERROR(minifs('Trade Log'!T5:T1004,'Trade Log'!G5:G1004,A36),"—"),"") | I36: =IF(A36<>"",IFERROR(AVERAGEIF('Trade Log'!G5:G1004,A36,'Trade Log'!W5:W1004),"—"),"") | J36: =IF(A36<>"",IFERROR(maxifs('Trade Log'!U5:U1004,'Trade Log'!G5:G1004,A36),"—"),"")
B37: =IF(A37<>"",COUNTIF('Trade Log'!G5:G1004,A37),"") | C37: =IF(A37<>"",IFERROR(SUMIF('Trade Log'!G5:G1004,A37,'Trade Log'!T5:T1004),"—"),"") | D37: =IF(A37<>"",IFERROR(COUNTIFS('Trade Log'!G5:G1004,A37,'Trade Log'!T5:T1004,">0")/COUNTIF('Trade Log'!G5:G1004,A37),"—"),"") | E37: =IF(A37<>"",IFERROR(AVERAGEIF('Trade Log'!G5:G1004,A37,'Trade Log'!T5:T1004),"—"),"") | F37: =IF(A37<>"",IFERROR(AVERAGEIF('Trade Log'!G5:G1004,A37,'Trade Log'!U5:U1004),"—"),"") | G37: =IF(A37<>"",IFERROR(maxifs('Trade Log'!T5:T1004,'Trade Log'!G5:G1004,A37),"—"),"") | H37: =IF(A37<>"",IFERROR(minifs('Trade Log'!T5:T1004,'Trade Log'!G5:G1004,A37),"—"),"") | I37: =IF(A37<>"",IFERROR(AVERAGEIF('Trade Log'!G5:G1004,A37,'Trade Log'!W5:W1004),"—"),"") | J37: =IF(A37<>"",IFERROR(maxifs('Trade Log'!U5:U1004,'Trade Log'!G5:G1004,A37),"—"),"")
B38: =IF(A38<>"",COUNTIF('Trade Log'!G5:G1004,A38),"") | C38: =IF(A38<>"",IFERROR(SUMIF('Trade Log'!G5:G1004,A38,'Trade Log'!T5:T1004),"—"),"") | D38: =IF(A38<>"",IFERROR(COUNTIFS('Trade Log'!G5:G1004,A38,'Trade Log'!T5:T1004,">0")/COUNTIF('Trade Log'!G5:G1004,A38),"—"),"") | E38: =IF(A38<>"",IFERROR(AVERAGEIF('Trade Log'!G5:G1004,A38,'Trade Log'!T5:T1004),"—"),"") | F38: =IF(A38<>"",IFERROR(AVERAGEIF('Trade Log'!G5:G1004,A38,'Trade Log'!U5:U1004),"—"),"") | G38: =IF(A38<>"",IFERROR(maxifs('Trade Log'!T5:T1004,'Trade Log'!G5:G1004,A38),"—"),"") | H38: =IF(A38<>"",IFERROR(minifs('Trade Log'!T5:T1004,'Trade Log'!G5:G1004,A38),"—"),"") | I38: =IF(A38<>"",IFERROR(AVERAGEIF('Trade Log'!G5:G1004,A38,'Trade Log'!W5:W1004),"—"),"") | J38: =IF(A38<>"",IFERROR(maxifs('Trade Log'!U5:U1004,'Trade Log'!G5:G1004,A38),"—"),"")
B39: =IF(A39<>"",COUNTIF('Trade Log'!G5:G1004,A39),"") | C39: =IF(A39<>"",IFERROR(SUMIF('Trade Log'!G5:G1004,A39,'Trade Log'!T5:T1004),"—"),"") | D39: =IF(A39<>"",IFERROR(COUNTIFS('Trade Log'!G5:G1004,A39,'Trade Log'!T5:T1004,">0")/COUNTIF('Trade Log'!G5:G1004,A39),"—"),"") | E39: =IF(A39<>"",IFERROR(AVERAGEIF('Trade Log'!G5:G1004,A39,'Trade Log'!T5:T1004),"—"),"") | F39: =IF(A39<>"",IFERROR(AVERAGEIF('Trade Log'!G5:G1004,A39,'Trade Log'!U5:U1004),"—"),"") | G39: =IF(A39<>"",IFERROR(maxifs('Trade Log'!T5:T1004,'Trade Log'!G5:G1004,A39),"—"),"") | H39: =IF(A39<>"",IFERROR(minifs('Trade Log'!T5:T1004,'Trade Log'!G5:G1004,A39),"—"),"") | I39: =IF(A39<>"",IFERROR(AVERAGEIF('Trade Log'!G5:G1004,A39,'Trade Log'!W5:W1004),"—"),"") | J39: =IF(A39<>"",IFERROR(maxifs('Trade Log'!U5:U1004,'Trade Log'!G5:G1004,A39),"—"),"")
B40: =IF(A40<>"",COUNTIF('Trade Log'!G5:G1004,A40),"") | C40: =IF(A40<>"",IFERROR(SUMIF('Trade Log'!G5:G1004,A40,'Trade Log'!T5:T1004),"—"),"") | D40: =IF(A40<>"",IFERROR(COUNTIFS('Trade Log'!G5:G1004,A40,'Trade Log'!T5:T1004,">0")/COUNTIF('Trade Log'!G5:G1004,A40),"—"),"") | E40: =IF(A40<>"",IFERROR(AVERAGEIF('Trade Log'!G5:G1004,A40,'Trade Log'!T5:T1004),"—"),"") | F40: =IF(A40<>"",IFERROR(AVERAGEIF('Trade Log'!G5:G1004,A40,'Trade Log'!U5:U1004),"—"),"") | G40: =IF(A40<>"",IFERROR(maxifs('Trade Log'!T5:T1004,'Trade Log'!G5:G1004,A40),"—"),"") | H40: =IF(A40<>"",IFERROR(minifs('Trade Log'!T5:T1004,'Trade Log'!G5:G1004,A40),"—"),"") | I40: =IF(A40<>"",IFERROR(AVERAGEIF('Trade Log'!G5:G1004,A40,'Trade Log'!W5:W1004),"—"),"") | J40: =IF(A40<>"",IFERROR(maxifs('Trade Log'!U5:U1004,'Trade Log'!G5:G1004,A40),"—"),"")
B41: =IF(A41<>"",COUNTIF('Trade Log'!G5:G1004,A41),"") | C41: =IF(A41<>"",IFERROR(SUMIF('Trade Log'!G5:G1004,A41,'Trade Log'!T5:T1004),"—"),"") | D41: =IF(A41<>"",IFERROR(COUNTIFS('Trade Log'!G5:G1004,A41,'Trade Log'!T5:T1004,">0")/COUNTIF('Trade Log'!G5:G1004,A41),"—"),"") | E41: =IF(A41<>"",IFERROR(AVERAGEIF('Trade Log'!G5:G1004,A41,'Trade Log'!T5:T1004),"—"),"") | F41: =IF(A41<>"",IFERROR(AVERAGEIF('Trade Log'!G5:G1004,A41,'Trade Log'!U5:U1004),"—"),"") | G41: =IF(A41<>"",IFERROR(maxifs('Trade Log'!T5:T1004,'Trade Log'!G5:G1004,A41),"—"),"") | H41: =IF(A41<>"",IFERROR(minifs('Trade Log'!T5:T1004,'Trade Log'!G5:G1004,A41),"—"),"") | I41: =IF(A41<>"",IFERROR(AVERAGEIF('Trade Log'!G5:G1004,A41,'Trade Log'!W5:W1004),"—"),"") | J41: =IF(A41<>"",IFERROR(maxifs('Trade Log'!U5:U1004,'Trade Log'!G5:G1004,A41),"—"),"")
B42: =IF(A42<>"",COUNTIF('Trade Log'!G5:G1004,A42),"") | C42: =IF(A42<>"",IFERROR(SUMIF('Trade Log'!G5:G1004,A42,'Trade Log'!T5:T1004),"—"),"") | D42: =IF(A42<>"",IFERROR(COUNTIFS('Trade Log'!G5:G1004,A42,'Trade Log'!T5:T1004,">0")/COUNTIF('Trade Log'!G5:G1004,A42),"—"),"") | E42: =IF(A42<>"",IFERROR(AVERAGEIF('Trade Log'!G5:G1004,A42,'Trade Log'!T5:T1004),"—"),"") | F42: =IF(A42<>"",IFERROR(AVERAGEIF('Trade Log'!G5:G1004,A42,'Trade Log'!U5:U1004),"—"),"") | G42: =IF(A42<>"",IFERROR(maxifs('Trade Log'!T5:T1004,'Trade Log'!G5:G1004,A42),"—"),"") | H42: =IF(A42<>"",IFERROR(minifs('Trade Log'!T5:T1004,'Trade Log'!G5:G1004,A42),"—"),"") | I42: =IF(A42<>"",IFERROR(AVERAGEIF('Trade Log'!G5:G1004,A42,'Trade Log'!W5:W1004),"—"),"") | J42: =IF(A42<>"",IFERROR(maxifs('Trade Log'!U5:U1004,'Trade Log'!G5:G1004,A42),"—"),"")
